Workbook
Name 弧盘下拉: OFFSET(弧盘!$A$2,MATCH(1,(弧盘!$F$3:$F$52=INDIRECT("C"&ROW()))*(弧盘!$A$3:$A$52<>""),0),0,COUNTIFS(弧盘!$F$3:$F$52,INDIRECT("C"&ROW()),弧盘!$A$3:$A$52,"<>"),1)

Sheet 云配队
J2: 异环云配队 V0.1.1 作者：静默之光 | AF2: 内测阶段，请勿转载
F3: 角色 | G3: 装备弧盘 | H3: 装备卡带 | I3: 觉醒数 | AF3: 统计区 | AG3: 贡献伤害 | AH3: 贡献倾陷 | AI3: 累计回能 | AJ3: 累计环合 | AK3: 其他伤害
F4: 娜娜莉 | G4: =VLOOKUP($F4,配装!$A$3:$AF$18,配装!$V$1,FALSE) -> 预备备 | H4: =VLOOKUP($F4,配装!$A$3:$AF$18,配装!$X$1,FALSE) -> 森林萤火之心 | I4: =VLOOKUP($F4,配装!$A$3:$AX$18,配装!$AX$1,FALSE) -> 0 | L4: e | M4: q | N4: 5a | O4: 5a副手 | P4: 闪反 | Q4: 闪反副手 | AB4: C觉追击 | AD4: 累计伤害 | AF4: =F4 -> 娜娜莉 | AG4: =中间!D2 -> 235058.87 | AH4: =中间!E2 -> 16.523 | AI4: =中间!F2 -> 76.3986 | AJ4: =中间!G2 -> 86.5 | AK4: =计算!Z10 -> 135077.57
F5: 主角 | G5: =VLOOKUP($F5,配装!$A$3:$AF$18,配装!$V$1,FALSE) -> 休息日 | H5: =VLOOKUP($F5,配装!$A$3:$AF$18,配装!$X$1,FALSE) -> 失落光芒 | I5: =VLOOKUP($F5,配装!$A$3:$AX$18,配装!$AX$1,FALSE) -> 3 | J5: e | K5: q | Y5: 援护 | AD5: =中间!D10+AG11 -> 719149.73 | AF5: =F5 -> 主角 | AG5: =中间!D3 -> 49667.023 | AH5: =中间!E3 -> 5.301167 | AI5: =中间!F3 -> 90.672534 | AJ5: =中间!G3 -> 100 | AK5: =中间!D6 -> 222831.55
F6: 阿德勒 | G6: =VLOOKUP($F6,配装!$A$3:$AF$18,配装!$V$1,FALSE) -> 勿忘伞 | H6: =VLOOKUP($F6,配装!$A$3:$AF$18,配装!$X$1,FALSE) -> 守卫王国 | I6: =VLOOKUP($F6,配装!$A$3:$AX$18,配装!$AX$1,FALSE) -> 6 | R6: q | S6: dot10跳 | T6: e | AD6: DPS | AF6: =F6 -> 阿德勒 | AG6: =中间!D4 -> 35076.199 | AH6: =中间!E4 -> 8.65 | AI6: =中间!F4 -> 70.3594 | AJ6: =中间!G4 -> 20.1 | AK6: =中间!D7 -> 0
F7: 九原 | G7: =VLOOKUP($F7,配装!$A$3:$AF$18,配装!$V$1,FALSE) -> 现实避难所 | H7: =VLOOKUP($F7,配装!$A$3:$AF$18,配装!$X$1,FALSE) -> 森林萤火之心 | I7: =VLOOKUP($F7,配装!$A$3:$AX$18,配装!$AX$1,FALSE) -> 1 | U7: q清算 | V7: 6枪 | W7: e | X7: dot | Y7: 援护 | Z7: q | AA7: 清算 | AD7: =IFERROR((AD5)/AD9,0) -> 44946.858 | AF7: =F7 -> 九原 | AG7: =中间!D5 -> 122780.92 | AH7: =中间!E5 -> 5.4 | AI7: =中间!F5 -> 140.3594 | AJ7: =中间!G5 -> 11.802 | AK7: =中间!D8 -> 0
F8: 角色等级 | G8: 怪物等级 | H8: 倾陷上限 | I8: 重复 | J8: 1 | K8: 0.667 | L8: 1 | M8: 0.75 | N8: 2 | O8: 0.75 | P8: 3 | Q8: 1.5 | R8: 0.5 | S8: 0.5 | T8: 1 | U8: 1 | V8: 1 | W8: 1 | X8: 12 | Y8: 1 | Z8: 1 | AA8: 1 | AB8: 12 | AC8: 1.5 | AD8: 累计时间 | AF8: 创生 | AG8: =中间!D6 -> 222831.55
F9: 80 | G9: 82 | H9: 70 | I9: 动作伤害 | J9: {=_xlfn._xlws.FILTER(计算!8:8,计算!1:1="d")} -> 13589.46 | K9: 27780.86 | L9: 29433.813 | M9: 49584.653 | N9: 61453.635 | O9: 18156.134 | P9: 30669.127 | Q9: 9430.186 | R9: 12814.91 | S9: 9026.2172 | T9: 13235.071 | U9: 25441.24 | V9: 10465.329 | W9: 15713.707 | X9: 22897.116 | Y9: 10475.805 | Z9: 31427.415 | AA9: 6360.3101 | AB9: 36331.326 | AC9: 0 | AD9: =IF(AD13>0,AD13,中间!D11) -> 16 | AF9: 浊燃 | AG9: =中间!D7 -> 0
F10: 怪物抗性 | G10: 怪物弱点 | H10: 弱点减抗 | I10: 累计耗时 | J10: {=_xlfn._xlws.FILTER(计算!8:8,计算!1:1="t")} -> 0.2 | K10: 0 | L10: 0 | M10: 0 | N10: 7.7 | O10: 0 | P10: 6.3 | Q10: 0 | R10: 0 | S10: 0 | T10: 0 | U10: 0 | V10: 0.3 | W10: 0 | X10: 0 | Y10: 1.3 | Z10: 0 | AA10: 0 | AB10: 0 | AC10: 0 | AD10: 累计倾陷 | AF10: 黯星 | AG10: =中间!D8 -> 0
F11: 0.2 | H11: 0.2 | I11: 反应 | AC11: 创生 | AD11: =中间!E10 -> 35.874167 | AF11: 倾陷 | AG11: =AK4*AE13 -> 53735.166
G12: 对敌类型 | H12: 早雾DOT 层数 | I12: 倾陷状态 | AD12: 指定轴长 | AE12: 倾陷频率
G13: BOSS | I13: 反应贡献 | J13: 全队最高 | K13: 全队最高 | L13: 全队最高 | M13: 全队最高 | N13: 全队最高 | O13: 全队最高 | P13: 全队最高 | Q13: 全队最高 | R13: 全队最高 | S13: 全队最高 | T13: 全队最高 | U13: 全队最高 | V13: 全队最高 | W13: 全队最高 | X13: 全队最高 | Y13: 全队最高 | Z13: 全队最高 | AA13: 全队最高 | AB13: 全队最高 | AC13: 全队最高 | AD13: 16 | AE13: =IFERROR(1/(H9/AD11+9/AD13),0) -> 0.39780969
G14: BUFF | I14: 自身buff1 | L14: 娜娜莉E暴伤 | M14: 娜娜莉E暴伤 | N14: 娜娜莉E暴伤 | O14: 娜娜莉E暴伤 | P14: 娜娜莉E暴伤 | Q14: 娜娜莉E暴伤 | S14: 阿德勒6命Q后E | AD14: 170595.75 | AE14: 654249.57
G15: 覆盖率 | H15: 0.5 | I15: 自身buff2 | T15: 阿德勒6命Q后E | AD15: =AG4/AD14 -> 1.3778706 | AE15: =AD5/AE14 -> 1.0991979
H16: 0.5 | I16: 全队buff1
I17: 全队buff2
I18: 全队buff3
I19: 全队buff4
I20: 全队buff5
I21: 全队buff6
H22: 0.67 | I22: 卡带buff1 | J22: 光套减防 | AC22: 光套减防
H23: 0.5 | I23: 卡带buff2 | J23: 音速蓝刺猬 | K23: 音速蓝刺猬 | L23: 音速蓝刺猬 | M23: 音速蓝刺猬 | N23: 音速蓝刺猬 | O23: 音速蓝刺猬 | P23: 音速蓝刺猬 | Q23: 音速蓝刺猬 | R23: 音速蓝刺猬 | S23: 音速蓝刺猬 | T23: 音速蓝刺猬 | U23: 音速蓝刺猬 | V23: 音速蓝刺猬 | W23: 音速蓝刺猬 | X23: 音速蓝刺猬 | Y23: 音速蓝刺猬 | Z23: 音速蓝刺猬 | AA23: 音速蓝刺猬 | AB23: 音速蓝刺猬 | AC23: 音速蓝刺猬
H24: 1 | I24: 卡带buff3 | K24: 光套减防
H25: 1 | I25: 卡带buff4
I26: 弧盘buff1 | M26: 预备备开Q非普攻 | O26: 预备备开Q普攻 | Q26: 预备备开Q普攻
H27: 0.75 | I27: 弧盘buff2 | N27: 预备备开Q普攻 | P27: 预备备开Q非普攻 | AB27: 预备备开Q非普攻
I28: 弧盘buff3
I29: 弧盘buff4

Sheet 配装
A1: =COLUMN() -> 1 | B1: =COLUMN() -> 2 | C1: =COLUMN() -> 3 | D1: =COLUMN() -> 4 | E1: =COLUMN() -> 5 | F1: =COLUMN() -> 6 | G1: =COLUMN() -> 7 | H1: =COLUMN() -> 8 | ... AZ1: =COLUMN() -> 52
A2: 角色 | B2: 属性 | C2: 适配 | D2: 基础攻击 | E2: 大攻击区 | F2: 小攻击区 | G2: 面板攻击 | H2: 基础生命 | I2: 大生命区 | J2: 小生命区 | K2: 面板生命 | L2: 基础防御 | M2: 大防御区 | N2: 小防御区 | O2: 面板防御 | P2: 面板暴击 | Q2: 面板暴伤 | R2: 面板属伤 | S2: 面板充能 | T2: 面板精通 | U2: 面板倾陷 | V2: 弧盘 | W2: 详情 | X2: 卡带 | Y2: 详情 | Z2: 技能等级 不含3命 | AA2: 等级区 | AB2: 卡带 主词条 | AC2: 空幕加成 | AD2: 空幕属性 | AE2: 空幕被动 | AF2: 空幕被动层数 | AG2: 全伤 1%/B | AH2: 暴击 1%/B | AI2: 暴伤 2%/B | AJ2: 精通 6/B | AK2: 倾陷强度 6/B | AL2: 攻击% 1.25%/B | AM2: 攻击 8/B | AN2: 生命% 1.25%/B | AO2: 生命 100/B | AP2: 防御% 1.75%/B | AQ2: 防御 8/B | AR2: 觉醒A | AS2: 觉醒B | AT2: 觉醒C | AU2: 觉醒D | AV2: 觉醒E | AW2: 觉醒F | AX2: 觉醒数 | AY2: 3命 | AZ2: 6命
A3: 主角 | B3: =角色!B3 -> 光 | C3: 固态 | D3: =角色!D3+VLOOKUP($V3,弧盘!$A$2:$C$51,弧盘!$B$1,FALSE) -> 1187.75 | E3: =角色!L3+VLOOKUP($V3,弧盘!$A$2:$AF$51,弧盘!$I$1,FALSE)+VLOOKUP($X3,卡带!$A$2:$V$14,卡带!$C$1,FALSE)+IF($AB3="攻击",中间!$M$7,0)+IF($AD3="攻击",$AF3*$AC3%,0)+AL3 -> 0.725 | F3: =AM3+角色!M3+中间!$L$20 -> 420 | G3: =D3*(1+E3)+F3 -> 2468.8688 | H3: =角色!F3 -> 15150 | I3: =角色!N3+VLOOKUP($V3,弧盘!$A$2:$AF$51,弧盘!$J$1,FALSE)+VLOOKUP($X3,卡带!$A$2:$V$14,卡带!$D$1,FALSE)+IF($AB3="生命",中间!$M$8,0)+IF($AD3="生命",$AF3*$AC3%,0)+AN3 -> 0 | J3: =AO3+角色!O3+中间!$L$21 -> 5200 | K3: =H3*(1+I3)+J3 -> 20350 | L3: =角色!H3 -> 909 | M3: =角色!P3+VLOOKUP($V3,弧盘!$A$2:$AF$51,弧盘!$K$1,FALSE)+VLOOKUP($X3,卡带!$A$2:$V$14,卡带!$E$1,FALSE)+IF($AB3="防御",中间!$M$9,0)+IF($AD3="防御",$AF3*$AC3%,0)+AR3 -> 0 | N3: =AQ3+角色!Q3 -> 0 | O3: =L3*(1+M3)+N3 -> 909 | P3: =角色!J3+VLOOKUP($V3,弧盘!$A$2:$AF$51,弧盘!$G$1,FALSE)+IF(AB3="暴击",中间!$M$3,0)+AH3+IF($AD3="暴击",$AC3%*$AF3,0) -> 0.15 | Q3: =角色!K3+VLOOKUP($V3,弧盘!$A$2:$AF$51,弧盘!$H$1,FALSE)+IF(AB3="暴伤",中间!$M$4,0)+IF($AD3="暴伤",$AC3%*$AF3,0)+AI3 -> 0.7 | R3: =角色!X3+VLOOKUP($X3,卡带!A$3:B$15,卡带!$B$1,FALSE)+IF(AB3="属伤",中间!$M$2,0)+IF($AD3="属伤",$AC3%*$AF3,0) -> 0.1 | S3: =角色!T3+VLOOKUP($V3,弧盘!$A$2:$AF$51,弧盘!$L$1,FALSE)+VLOOKUP($X3,卡带!A$3:F$15,卡带!$F$1,FALSE)+IF($AD3="充能",$AC3%*$AF3,0) -> 0.33 | T3: =角色!U3+VLOOKUP($V3,弧盘!$A$2:$AF$51,弧盘!M$1,FALSE)+VLOOKUP($X3,卡带!$A$2:$V$14,卡带!G$1,FALSE)+IF($AB3="精通",中间!$M$5,0)+IF($AD3="精通",$AC3%*$AF3,0)+AJ3 -> 270 | U3: =角色!V3+VLOOKUP($V3,弧盘!$A$2:$AF$51,弧盘!N$1,FALSE)+VLOOKUP($X3,卡带!$A$2:$V$14,卡带!H$1,FALSE)+IF($AB3="倾陷",中间!$M$6,0)+AK3 -> 0 | V3: 休息日 | W3: =IFERROR(VLOOKUP(V3,弧盘!$A$2:O53,弧盘!$O$1,FALSE),"") -> 30攻击；调弧：对群回能 | X3: 失落光芒 | Y3: =IFERROR(VLOOKUP(X3,卡带!$A$2:$J$14,卡带!$J$1,FALSE),"") -> 10光伤；Q后20秒减防25 | Z3: 10 | AA3: =POWER(1.08,Z3-1+IF(AY3,1,0)) -> 2.158925 | AB3: 精通 | AC3: 10 | AD3: 攻击 | AE3: =AC3&AD3 -> 10攻击 | AF3: 6 | AG3: 0.15 | AH3: 0.1 | AI3: 0.2 | AJ3: 90 | AL3: 0.125 | AS3: TRUE | AT3: TRUE | AU3: TRUE | AX3: =COUNTIF($AR3:$AW3,TRUE) -> 3 | AY3: =AX3>2 -> TRUE | AZ3: =AX3>5 -> FALSE
A4: 浔 | B4: =角色!B4 -> 光 | C4: 固态 | D4: =角色!D4+VLOOKUP($V4,弧盘!$A$2:$C$51,弧盘!$B$1,FALSE) -> 1206 | E4: =角色!L4+VLOOKUP($V4,弧盘!$A$2:$AF$51,弧盘!$I$1,FALSE)+VLOOKUP($X4,卡带!$A$2:$V$14,卡带!$C$1,FALSE)+IF($AB4="攻击",中间!$M$7,0)+IF($AD4="攻击",$AF4*$AC4%,0)+AL4 -> 0.1875 | F4: =AM4+角色!M4+中间!$L$20 -> 420 | G4: =D4*(1+E4)+F4 -> 1852.125 | H4: =角色!F4 -> 15998.4 | I4: =角色!N4+VLOOKUP($V4,弧盘!$A$2:$AF$51,弧盘!$J$1,FALSE)+VLOOKUP($X4,卡带!$A$2:$V$14,卡带!$D$1,FALSE)+IF($AB4="生命",中间!$M$8,0)+IF($AD4="生命",$AF4*$AC4%,0)+AN4 -> 0 | J4: =AO4+角色!O4+中间!$L$21 -> 5200 | K4: =H4*(1+I4)+J4 -> 21198.4 | L4: =角色!H4 -> 909 | M4: =角色!P4+VLOOKUP($V4,弧盘!$A$2:$AF$51,弧盘!$K$1,FALSE)+VLOOKUP($X4,卡带!$A$2:$V$14,卡带!$E$1,FALSE)+IF($AB4="防御",中间!$M$9,0)+IF($AD4="防御",$AF4*$AC4%,0)+AR4 -> 0 | N4: =AQ4+角色!Q4 -> 0 | O4: =L4*(1+M4)+N4 -> 909 | P4: =角色!J4+VLOOKUP($V4,弧盘!$A$2:$AF$51,弧盘!$G$1,FALSE)+IF(AB4="暴击",中间!$M$3,0)+AH4+IF($AD4="暴击",$AC4%*$AF4,0) -> 0.74 | Q4: =角色!K4+VLOOKUP($V4,弧盘!$A$2:$AF$51,弧盘!$H$1,FALSE)+IF(AB4="暴伤",中间!$M$4,0)+IF($AD4="暴伤",$AC4%*$AF4,0)+AI4 -> 0.8 | R4: =角色!X4+VLOOKUP($X4,卡带!A$3:B$15,卡带!$B$1,FALSE)+IF(AB4="属伤",中间!$M$2,0)+IF($AD4="属伤",$AC4%*$AF4,0) -> 0.5 | S4: =角色!T4+VLOOKUP($V4,弧盘!$A$2:$AF$51,弧盘!$L$1,FALSE)+VLOOKUP($X4,卡带!A$3:F$15,卡带!$F$1,FALSE)+IF($AD4="充能",$AC4%*$AF4,0) -> 0 | T4: =角色!U4+VLOOKUP($V4,弧盘!$A$2:$AF$51,弧盘!M$1,FALSE)+VLOOKUP($X4,卡带!$A$2:$V$14,卡带!G$1,FALSE)+IF($AB4="精通",中间!$M$5,0)+IF($AD4="精通",$AC4%*$AF4,0)+AJ4 -> 0 | U4: =角色!V4+VLOOKUP($V4,弧盘!$A$2:$AF$51,弧盘!N$1,FALSE)+VLOOKUP($X4,卡带!$A$2:$V$14,卡带!H$1,FALSE)+IF($AB4="倾陷",中间!$M$6,0)+AK4 -> 0 | V4: 行进于时间之外 | W4: =IFERROR(VLOOKUP(V4,弧盘!$A$2:O54,弧盘!$O$1,FALSE),"") -> 16攻击；e后每秒q的45暴伤和12减防 | X4: 失落光芒 | Y4: =IFERROR(VLOOKUP(X4,卡带!$A$2:$J$14,卡带!$J$1,FALSE),"") -> 10光伤；Q后20秒减防25 | Z4: 10 | AA4: =POWER(1.08,Z4-1+IF(AY4,1,0)) -> 1.9990046 | AB4: 暴击 | AC4: 10 | AD4: 属伤 | AE4: =AC4&AD4 -> 10属伤 | AF4: 4 | AG4: 0.15 | AH4: 0.15 | AI4: 0.3 | AL4: =15*1.25% -> 0.1875 | AX4: =COUNTIF($AR4:$AW4,TRUE) -> 0 | AY4: =AX4>2 -> FALSE | AZ4: =AX4>5 -> FALSE
A5: 小吱 | B5: 光 | C5: 气态 | D5: =角色!D5+VLOOKUP($V5,弧盘!$A$2:$C$51,弧盘!$B$1,FALSE) -> 1171.85 | E5: =角色!L5+VLOOKUP($V5,弧盘!$A$2:$AF$51,弧盘!$I$1,FALSE)+VLOOKUP($X5,卡带!$A$2:$V$14,卡带!$C$1,FALSE)+IF($AB5="攻击",中间!$M$7,0)+IF($AD5="攻击",$AF5*$AC5%,0)+AL5 -> 0.1875 | F5: =AM5+角色!M5+中间!$L$20 -> 420 | G5: =D5*(1+E5)+F5 -> 1811.5719 | H5: =角色!F5 -> 15513.6 | I5: =角色!N5+VLOOKUP($V5,弧盘!$A$2:$AF$51,弧盘!$J$1,FALSE)+VLOOKUP($X5,卡带!$A$2:$V$14,卡带!$D$1,FALSE)+IF($AB5="生命",中间!$M$8,0)+IF($AD5="生命",$AF5*$AC5%,0)+AN5 -> 0 | J5: =AO5+角色!O5+中间!$L$21 -> 5200 | K5: =H5*(1+I5)+J5 -> 20713.6 | L5: =角色!H5 -> 909 | M5: =角色!P5+VLOOKUP($V5,弧盘!$A$2:$AF$51,弧盘!$K$1,FALSE)+VLOOKUP($X5,卡带!$A$2:$V$14,卡带!$E$1,FALSE)+IF($AB5="防御",中间!$M$9,0)+IF($AD5="防御",$AF5*$AC5%,0)+AR5 -> 1 | N5: =AQ5+角色!Q5 -> 0 | O5: =L5*(1+M5)+N5 -> 1818 | P5: =角色!J5+VLOOKUP($V5,弧盘!$A$2:$AF$51,弧盘!$G$1,FALSE)+IF(AB5="暴击",中间!$M$3,0)+AH5+IF($AD5="暴击",$AC5%*$AF5,0) -> 0.5 | Q5: =角色!K5+VLOOKUP($V5,弧盘!$A$2:$AF$51,弧盘!$H$1,FALSE)+IF(AB5="暴伤",中间!$M$4,0)+IF($AD5="暴伤",$AC5%*$AF5,0)+AI5 -> 1.24 | R5: =角色!X5+VLOOKUP($X5,卡带!A$3:B$15,卡带!$B$1,FALSE)+IF(AB5="属伤",中间!$M$2,0)+IF($AD5="属伤",$AC5%*$AF5,0) -> 0.7 | S5: =角色!T5+VLOOKUP($V5,弧盘!$A$2:$AF$51,弧盘!$L$1,FALSE)+VLOOKUP($X5,卡带!A$3:F$15,卡带!$F$1,FALSE)+IF($AD5="充能",$AC5%*$AF5,0) -> 0 | T5: =角色!U5+VLOOKUP($V5,弧盘!$A$2:$AF$51,弧盘!M$1,FALSE)+VLOOKUP($X5,卡带!$A$2:$V$14,卡带!G$1,FALSE)+IF($AB5="精通",中间!$M$5,0)+IF($AD5="精通",$AC5%*$AF5,0)+AJ5 -> 0 | U5: =角色!V5+VLOOKUP($V5,弧盘!$A$2:$AF$51,弧盘!N$1,FALSE)+VLOOKUP($X5,卡带!$A$2:$V$14,卡带!H$1,FALSE)+IF($AB5="倾陷",中间!$M$6,0)+AK5 -> 0 | V5: 思考喵 | W5: =IFERROR(VLOOKUP(V5,弧盘!$A$2:O55,弧盘!$O$1,FALSE),"") -> 100万方斯叠满25光伤 | X5: 失落光芒 | Y5: =IFERROR(VLOOKUP(X5,卡带!$A$2:$J$14,卡带!$J$1,FALSE),"") -> 10光伤；Q后20秒减防25 | Z5: 10 | AA5: =POWER(1.08,Z5-1) -> 1.9990046 | AB5: 暴击 | AC5: 10 | AD5: 属伤 | AE5: =AC5&AD5 -> 10属伤 | AF5: 4 | AG5: 0.15 | AH5: 0.15 | AI5: 0.3 | AL5: =15*1.25% -> 0.1875 | AR5: TRUE | AW5: TRUE | AX5: =COUNTIF($AR5:$AW5,TRUE) -> 2 | AY5: =AX5>2 -> FALSE | AZ5: =AX5>5 -> FALSE
A6: 埃德嘉 | B6: 光 | C6: 液态 | D6: =角色!D6+VLOOKUP($V6,弧盘!$A$2:$C$51,弧盘!$B$1,FALSE) -> 816.35 | E6: =角色!L6+VLOOKUP($V6,弧盘!$A$2:$AF$51,弧盘!$I$1,FALSE)+VLOOKUP($X6,卡带!$A$2:$V$14,卡带!$C$1,FALSE)+IF($AB6="攻击",中间!$M$7,0)+IF($AD6="攻击",$AF6*$AC6%,0)+AN6 -> 0.1875 | F6: =AM6+角色!M6+中间!$L$20 -> 420 | G6: =D6*(1+E6)+F6 -> 1389.4156 | H6: =角色!F6 -> 16362 | I6: =角色!N6+VLOOKUP($V6,弧盘!$A$2:$AF$51,弧盘!$J$1,FALSE)+VLOOKUP($X6,卡带!$A$2:$V$14,卡带!$D$1,FALSE)+IF($AB6="生命",中间!$M$8,0)+IF($AD6="生命",$AF6*$AC6%,0)+AN6 -> 1.2625 | J6: =AO6+角色!O6+中间!$L$21 -> 5200 | K6: =H6*(1+I6)+J6 -> 42219.025 | L6: =角色!H6 -> 824.16 | M6: =角色!P6+VLOOKUP($V6,弧盘!$A$2:$AF$51,弧盘!$K$1,FALSE)+VLOOKUP($X6,卡带!$A$2:$V$14,卡带!$E$1,FALSE)+IF($AB6="防御",中间!$M$9,0)+IF($AD6="防御",$AF6*$AC6%,0)+AR6 -> 1 | N6: =AQ6+角色!Q6 -> 0 | O6: =L6*(1+M6)+N6 -> 1648.32 | P6: =角色!J6+VLOOKUP($V6,弧盘!$A$2:$AF$51,弧盘!$G$1,FALSE)+IF(AB6="暴击",中间!$M$3,0)+AH6+IF($AD6="暴击",$AC6%*$AF6,0) -> 0.2 | Q6: =角色!K6+VLOOKUP($V6,弧盘!$A$2:$AF$51,弧盘!$H$1,FALSE)+IF(AB6="暴伤",中间!$M$4,0)+IF($AD6="暴伤",$AC6%*$AF6,0)+AI6 -> 0.8 | R6: =角色!X6+VLOOKUP($X6,卡带!A$3:B$15,卡带!$B$1,FALSE)+IF(AB6="属伤",中间!$M$2,0)+IF($AD6="属伤",$AC6%*$AF6,0) -> 0 | S6: =角色!T6+VLOOKUP($V6,弧盘!$A$2:$AF$51,弧盘!$L$1,FALSE)+VLOOKUP($X6,卡带!A$3:F$15,卡带!$F$1,FALSE)+IF($AD6="充能",$AC6%*$AF6,0) -> 0 | T6: =角色!U6+VLOOKUP($V6,弧盘!$A$2:$AF$51,弧盘!M$1,FALSE)+VLOOKUP($X6,卡带!$A$2:$V$14,卡带!G$1,FALSE)+IF($AB6="精通",中间!$M$5,0)+IF($AD6="精通",$AC6%*$AF6,0)+AJ6 -> 0 | U6: =角色!V6+VLOOKUP($V6,弧盘!$A$2:$AF$51,弧盘!N$1,FALSE)+VLOOKUP($X6,卡带!$A$2:$V$14,卡带!H$1,FALSE)+IF($AB6="倾陷",中间!$M$6,0)+AK6 -> 0 | V6: 扭曲之城的呼唤 | W6: =IFERROR(VLOOKUP(V6,弧盘!$A$2:O56,弧盘!$O$1,FALSE),"") -> e后治疗效率20% | X6: 缇娅的夜间酒馆 | Y6: =IFERROR(VLOOKUP(X6,卡带!$A$2:$J$14,卡带!$J$1,FALSE),"") -> 10生命；20%治疗效率 | Z6: 10 | AA6: =POWER(1.08,Z6-1+IF(AY6,1,0)) -> 2.158925 | AB6: 治疗 | AC6: 10 | AD6: 生命 | AE6: =AC6&AD6 -> 10生命 | AF6: 6 | AG6: 0.15 | AH6: 0.15 | AI6: 0.3 | AN6: =15*1.25% -> 0.1875 | AR6: TRUE | AS6: TRUE | AT6: TRUE | AU6: TRUE | AV6: TRUE | AW6: TRUE | AX6: =COUNTIF($AR6:$AW6,TRUE) -> 6 | AY6: =AX6>2 -> TRUE | AZ6: =AX6>5 -> TRUE
A7: 娜娜莉 | B7: =角色!B7 -> 灵 | C7: 等离子 | D7: =角色!D7+VLOOKUP($V7,弧盘!$A$2:$C$51,弧盘!$B$1,FALSE) -> 1206 | E7: =角色!L7+VLOOKUP($V7,弧盘!$A$2:$AF$51,弧盘!$I$1,FALSE)+VLOOKUP($X7,卡带!$A$2:$V$14,卡带!$C$1,FALSE)+IF($AB7="攻击",中间!$M$7,0)+IF($AD7="攻击",$AF7*$AC7%,0)+AL7 -> 0.1875 | F7: =AM7+角色!M7+中间!$L$20 -> 420 | G7: =D7*(1+E7)+F7 -> 1852.125 | H7: =角色!F7 -> 15998.4 | I7: =角色!N7+VLOOKUP($V7,弧盘!$A$2:$AF$51,弧盘!$J$1,FALSE)+VLOOKUP($X7,卡带!$A$2:$V$14,卡带!$D$1,FALSE)+IF($AB7="生命",中间!$M$8,0)+IF($AD7="生命",$AF7*$AC7%,0)+AN7 -> 0 | J7: =AO7+角色!O7+中间!$L$21 -> 5200 | K7: =H7*(1+I7)+J7 -> 21198.4 | L7: =角色!H7 -> 909 | M7: =角色!P7+VLOOKUP($V7,弧盘!$A$2:$AF$51,弧盘!$K$1,FALSE)+VLOOKUP($X7,卡带!$A$2:$V$14,卡带!$E$1,FALSE)+IF($AB7="防御",中间!$M$9,0)+IF($AD7="防御",$AF7*$AC7%,0)+AR7 -> 0 | N7: =AQ7+角色!Q7 -> 0 | O7: =L7*(1+M7)+N7 -> 909 | P7: =角色!J7+VLOOKUP($V7,弧盘!$A$2:$AF$51,弧盘!$G$1,FALSE)+IF(AB7="暴击",中间!$M$3,0)+AH7+IF($AD7="暴击",$AC7%*$AF7,0) -> 0.69 | Q7: =角色!K7+VLOOKUP($V7,弧盘!$A$2:$AF$51,弧盘!$H$1,FALSE)+IF(AB7="暴伤",中间!$M$4,0)+IF($AD7="暴伤",$AC7%*$AF7,0)+AI7 -> 0.8 | R7: =角色!X7+VLOOKUP($X7,卡带!A$3:B$15,卡带!$B$1,FALSE)+IF(AB7="属伤",中间!$M$2,0)+IF($AD7="属伤",$AC7%*$AF7,0) -> 0.475 | S7: =角色!T7+VLOOKUP($V7,弧盘!$A$2:$AF$51,弧盘!$L$1,FALSE)+VLOOKUP($X7,卡带!A$3:F$15,卡带!$F$1,FALSE)+IF($AD7="充能",$AC7%*$AF7,0) -> 0 | T7: =角色!U7+VLOOKUP($V7,弧盘!$A$2:$AF$51,弧盘!M$1,FALSE)+VLOOKUP($X7,卡带!$A$2:$V$14,卡带!G$1,FALSE)+IF($AB7="精通",中间!$M$5,0)+IF($AD7="精通",$AC7%*$AF7,0)+AJ7 -> 0 | U7: =角色!V7+VLOOKUP($V7,弧盘!$A$2:$AF$51,弧盘!N$1,FALSE)+VLOOKUP($X7,卡带!$A$2:$V$14,卡带!H$1,FALSE)+IF($AB7="倾陷",中间!$M$6,0)+AK7 -> 0 | V7: 预备备 | W7: =IFERROR(VLOOKUP(V7,弧盘!$A$2:O56,弧盘!$O$1,FALSE),"") -> 15攻击；eq后普攻增伤15%，15秒2层；调弧(eq)：10对boss增伤，10秒 | X7: 森林萤火之心 | Y7: =IFERROR(VLOOKUP(X7,卡带!$A$2:$J$14,卡带!$J$1,FALSE),"") -> 10灵伤；8暴伤*7，10秒 | Z7: 10 | AA7: =POWER(1.08,Z7-1+IF(AY7,1,0)) -> 1.9990046 | AB7: 属伤 | AC7: 5 | AD7: 暴击 | AE7: =AC7&AD7 -> 5暴击 | AF7: 5 | AG7: 0.15 | AH7: 0.15 | AI7: 0.3 | AL7: =15*1.25% -> 0.1875 | AX7: =COUNTIF($AR7:$AW7,TRUE) -> 0 | AY7: =AX7>2 -> FALSE | AZ7: =AX7>5 -> FALSE
A8: 九原 | B8: =角色!B8 -> 灵 | C8: 固态 | D8: =角色!D8+VLOOKUP($V8,弧盘!$A$2:$C$51,弧盘!$B$1,FALSE) -> 1221.9 | E8: =角色!L8+VLOOKUP($V8,弧盘!$A$2:$AF$51,弧盘!$I$1,FALSE)+VLOOKUP($X8,卡带!$A$2:$V$14,卡带!$C$1,FALSE)+IF($AB8="攻击",中间!$M$7,0)+IF($AD8="攻击",$AF8*$AC8%,0)+AL8 -> 0.4875 | F8: =AM8+角色!M8+中间!$L$20 -> 420 | G8: =D8*(1+E8)+F8 -> 2237.5763 | H8: =角色!F8 -> 15634.8 | I8: =角色!N8+VLOOKUP($V8,弧盘!$A$2:$AF$51,弧盘!$J$1,FALSE)+VLOOKUP($X8,卡带!$A$2:$V$14,卡带!$D$1,FALSE)+IF($AB8="生命",中间!$M$8,0)+IF($AD8="生命",$AF8*$AC8%,0)+AN8 -> 0 | J8: =AO8+角色!O8+中间!$L$21 -> 5200 | K8: =H8*(1+I8)+J8 -> 20834.8 | L8: =角色!H8 -> 909 | M8: =角色!P8+VLOOKUP($V8,弧盘!$A$2:$AF$51,弧盘!$K$1,FALSE)+VLOOKUP($X8,卡带!$A$2:$V$14,卡带!$E$1,FALSE)+IF($AB8="防御",中间!$M$9,0)+IF($AD8="防御",$AF8*$AC8%,0)+AR8 -> 0 | N8: =AQ8+角色!Q8 -> 0 | O8: =L8*(1+M8)+N8 -> 909 | P8: =角色!J8+VLOOKUP($V8,弧盘!$A$2:$AF$51,弧盘!$G$1,FALSE)+IF(AB8="暴击",中间!$M$3,0)+AH8+IF($AD8="暴击",$AC8%*$AF8,0) -> 0.75 | Q8: =角色!K8+VLOOKUP($V8,弧盘!$A$2:$AF$51,弧盘!$H$1,FALSE)+IF(AB8="暴伤",中间!$M$4,0)+IF($AD8="暴伤",$AC8%*$AF8,0)+AI8 -> 0.8 | R8: =角色!X8+VLOOKUP($X8,卡带!A$3:B$15,卡带!$B$1,FALSE)+IF(AB8="属伤",中间!$M$2,0)+IF($AD8="属伤",$AC8%*$AF8,0) -> 0.1 | S8: =角色!T8+VLOOKUP($V8,弧盘!$A$2:$AF$51,弧盘!$L$1,FALSE)+VLOOKUP($X8,卡带!A$3:F$15,卡带!$F$1,FALSE)+IF($AD8="充能",$AC8%*$AF8,0) -> 0 | T8: =角色!U8+VLOOKUP($V8,弧盘!$A$2:$AF$51,弧盘!M$1,FALSE)+VLOOKUP($X8,卡带!$A$2:$V$14,卡带!G$1,FALSE)+IF($AB8="精通",中间!$M$5,0)+IF($AD8="精通",$AC8%*$AF8,0)+AJ8 -> 0 | U8: =角色!V8+VLOOKUP($V8,弧盘!$A$2:$AF$51,弧盘!N$1,FALSE)+VLOOKUP($X8,卡带!$A$2:$V$14,卡带!H$1,FALSE)+IF($AB8="倾陷",中间!$M$6,0)+AK8 -> 0 | V8: 现实避难所 | W8: =IFERROR(VLOOKUP(V8,弧盘!$A$2:O57,弧盘!$O$1,FALSE),"") -> 15灵伤；10附着伤，q后改20附着伤 | X8: 森林萤火之心 | Y8: =IFERROR(VLOOKUP(X8,卡带!$A$2:$J$14,卡带!$J$1,FALSE),"") -> 10灵伤；8暴伤*7，10秒 | Z8: 10 | AA8: =POWER(1.08,Z8-1+IF(AY8,1,0)) -> 1.9990046 | AB8: 暴击 | AC8: 5 | AD8: 暴击 | AE8: =AC8&AD8 -> 5暴击 | AF8: 5 | AG8: 0.15 | AH8: 0.15 | AI8: 0.3 | AL8: =15*1.25% -> 0.1875 | AS8: TRUE | AX8: =COUNTIF($AR8:$AW8,TRUE) -> 1 | AY8: =AX8>2 -> FALSE | AZ8: =AX8>5 -> FALSE
A9: 薄荷 | B9: =角色!B9 -> 灵 | C9: 液态 | D9: =角色!D9+VLOOKUP($V9,弧盘!$A$2:$C$51,弧盘!$B$1,FALSE) -> 1071.25 | E9: =角色!L9+VLOOKUP($V9,弧盘!$A$2:$AF$51,弧盘!$I$1,FALSE)+VLOOKUP($X9,卡带!$A$2:$V$14,卡带!$C$1,FALSE)+IF($AB9="攻击",中间!$M$7,0)+IF($AD9="攻击",$AF9*$AC9%,0)+AL9 -> 0.4375 | F9: =AM9+角色!M9+中间!$L$20 -> 420 | G9: =D9*(1+E9)+F9 -> 1959.9219 | H9: =角色!F9 -> 12120 | I9: =角色!N9+VLOOKUP($V9,弧盘!$A$2:$AF$51,弧盘!$J$1,FALSE)+VLOOKUP($X9,卡带!$A$2:$V$14,卡带!$D$1,FALSE)+IF($AB9="生命",中间!$M$8,0)+IF($AD9="生命",$AF9*$AC9%,0)+AN9 -> 0 | J9: =AO9+角色!O9+中间!$L$21 -> 5200 | K9: =H9*(1+I9)+J9 -> 17320 | L9: =角色!H9 -> 727.2 | M9: =角色!P9+VLOOKUP($V9,弧盘!$A$2:$AF$51,弧盘!$K$1,FALSE)+VLOOKUP($X9,卡带!$A$2:$V$14,卡带!$E$1,FALSE)+IF($AB9="防御",中间!$M$9,0)+IF($AD9="防御",$AF9*$AC9%,0)+AR9 -> 1.2 | N9: =AQ9+角色!Q9 -> 0 | O9: =L9*(1+M9)+N9 -> 1599.84 | P9: =角色!J9+VLOOKUP($V9,弧盘!$A$2:$AF$51,弧盘!$G$1,FALSE)+IF(AB9="暴击",中间!$M$3,0)+AH9+IF($AD9="暴击",$AC9%*$AF9,0) -> 0.64 | Q9: =角色!K9+VLOOKUP($V9,弧盘!$A$2:$AF$51,弧盘!$H$1,FALSE)+IF(AB9="暴伤",中间!$M$4,0)+IF($AD9="暴伤",$AC9%*$AF9,0)+AI9 -> 1.05 | R9: =角色!X9+VLOOKUP($X9,卡带!A$3:B$15,卡带!$B$1,FALSE)+IF(AB9="属伤",中间!$M$2,0)+IF($AD9="属伤",$AC9%*$AF9,0) -> 0.475 | S9: =角色!T9+VLOOKUP($V9,弧盘!$A$2:$AF$51,弧盘!$L$1,FALSE)+VLOOKUP($X9,卡带!A$3:F$15,卡带!$F$1,FALSE)+IF($AD9="充能",$AC9%*$AF9,0) -> 0 | T9: =角色!U9+VLOOKUP($V9,弧盘!$A$2:$AF$51,弧盘!M$1,FALSE)+VLOOKUP($X9,卡带!$A$2:$V$14,卡带!G$1,FALSE)+IF($AB9="精通",中间!$M$5,0)+IF($AD9="精通",$AC9%*$AF9,0)+AJ9 -> 0 | U9: =角色!V9+VLOOKUP($V9,弧盘!$A$2:$AF$51,弧盘!N$1,FALSE)+VLOOKUP($X9,卡带!$A$2:$V$14,卡带!H$1,FALSE)+IF($AB9="倾陷",中间!$M$6,0)+AK9 -> 0 | V9: 开始净空 | W9: =IFERROR(VLOOKUP(V9,弧盘!$A$2:O58,弧盘!$O$1,FALSE),"") -> EQ35灵伤 | X9: 森林萤火之心 | Y9: =IFERROR(VLOOKUP(X9,卡带!$A$2:$J$14,卡带!$J$1,FALSE),"") -> 10灵伤；8暴伤*7，10秒 | Z9: 10 | AA9: =POWER(1.08,Z9-1+IF(AY9,1,0)) -> 2.158925 | AB9: 属伤 | AC9: 8 | AD9: 暴击 | AE9: =AC9&AD9 -> 8暴击 | AF9: 4 | AG9: 0.15 | AH9: 0.15 | AI9: 0.3 | AL9: =15*1.25% -> 0.1875 | AR9: TRUE | AS9: TRUE | AT9: TRUE | AU9: TRUE | AV9: TRUE | AW9: TRUE | AX9: =COUNTIF($AR9:$AW9,TRUE) -> 6 | AY9: =AX9>2 -> TRUE | AZ9: =AX9>5 -> TRUE
A10: 白藏 | B10: =角色!B10 -> 咒 | C10: 聚合 | D10: =角色!D10+VLOOKUP($V10,弧盘!$A$2:$C$51,弧盘!$B$1,FALSE) -> 1309.95 | E10: =角色!L10+VLOOKUP($V10,弧盘!$A$2:$AF$51,弧盘!$I$1,FALSE)+VLOOKUP($X10,卡带!$A$2:$V$14,卡带!$C$1,FALSE)+IF($AB10="攻击",中间!$M$7,0)+IF($AD10="攻击",$AF10*$AC10%,0)+AL10 -> 0.1875 | F10: =AM10+角色!M10+中间!$L$20 -> 420 | G10: =D10*(1+E10)+F10 -> 1975.5656 | H10: =角色!F10 -> 16604.4 | I10: =角色!N10+VLOOKUP($V10,弧盘!$A$2:$AF$51,弧盘!$J$1,FALSE)+VLOOKUP($X10,卡带!$A$2:$V$14,卡带!$D$1,FALSE)+IF($AB10="生命",中间!$M$8,0)+IF($AD10="生命",$AF10*$AC10%,0)+AN10 -> 0 | J10: =AO10+角色!O10+中间!$L$21 -> 5200 | K10: =H10*(1+I10)+J10 -> 21804.4 | L10: =角色!H10 -> 799.92 | M10: =角色!P10+VLOOKUP($V10,弧盘!$A$2:$AF$51,弧盘!$K$1,FALSE)+VLOOKUP($X10,卡带!$A$2:$V$14,卡带!$E$1,FALSE)+IF($AB10="防御",中间!$M$9,0)+IF($AD10="防御",$AF10*$AC10%,0)+AR10 -> 0 | N10: =AQ10+角色!Q10 -> 0 | O10: =L10*(1+M10)+N10 -> 799.92 | P10: =角色!J10+VLOOKUP($V10,弧盘!$A$2:$AF$51,弧盘!$G$1,FALSE)+IF(AB10="暴击",中间!$M$3,0)+AH10+IF($AD10="暴击",$AC10%*$AF10,0) -> 0.64 | Q10: =角色!K10+VLOOKUP($V10,弧盘!$A$2:$AF$51,弧盘!$H$1,FALSE)+IF(AB10="暴伤",中间!$M$4,0)+IF($AD10="暴伤",$AC10%*$AF10,0)+AI10 -> 0.8 | R10: =角色!X10+VLOOKUP($X10,卡带!A$3:B$15,卡带!$B$1,FALSE)+IF(AB10="属伤",中间!$M$2,0)+IF($AD10="属伤",$AC10%*$AF10,0) -> 0.475 | S10: =角色!T10+VLOOKUP($V10,弧盘!$A$2:$AF$51,弧盘!$L$1,FALSE)+VLOOKUP($X10,卡带!A$3:F$15,卡带!$F$1,FALSE)+IF($AD10="充能",$AC10%*$AF10,0) -> 0 | T10: =角色!U10+VLOOKUP($V10,弧盘!$A$2:$AF$51,弧盘!M$1,FALSE)+VLOOKUP($X10,卡带!$A$2:$V$14,卡带!G$1,FALSE)+IF($AB10="精通",中间!$M$5,0)+IF($AD10="精通",$AC10%*$AF10,0)+AJ10 -> 0 | U10: =角色!V10+VLOOKUP($V10,弧盘!$A$2:$AF$51,弧盘!N$1,FALSE)+VLOOKUP($X10,卡带!$A$2:$V$14,卡带!H$1,FALSE)+IF($AB10="倾陷",中间!$M$6,0)+AK10 -> 0 | V10: 茶花会 | W10: =IFERROR(VLOOKUP(V10,弧盘!$A$2:O59,弧盘!$O$1,FALSE),"") -> 扣血后12暴伤*4，5秒；调弧120倍率 | X10: 真红：双生蝶 | Y10: =IFERROR(VLOOKUP(X10,卡带!$A$2:$J$14,卡带!$J$1,FALSE),"") -> 10咒伤；6攻击*6，10秒 | Z10: 10 | AA10: =POWER(1.08,Z10-1+IF(AY10,1,0)) -> 1.9990046 | AB10: 属伤 | AC10: 8 | AD10: 暴击 | AE10: =AC10&AD10 -> 8暴击 | AF10: 4 | AG10: 0.15 | AH10: 0.15 | AI10: 0.3 | AL10: =15*1.25% -> 0.1875 | AX10: =COUNTIF($AR10:$AW10,TRUE) -> 0 | AY10: =AX10>2 -> FALSE | AZ10: =AX10>5 -> FALSE
A11: 早雾 | B11: =角色!B11 -> 咒 | C11: 气态 | D11: =角色!D11+VLOOKUP($V11,弧盘!$A$2:$C$51,弧盘!$B$1,FALSE) -> 1094.1 | E11: =角色!L11+VLOOKUP($V11,弧盘!$A$2:$AF$51,弧盘!$I$1,FALSE)+VLOOKUP($X11,卡带!$A$2:$V$14,卡带!$C$1,FALSE)+IF($AB11="攻击",中间!$M$7,0)+IF($AD11="攻击",$AF11*$AC11%,0)+AL11 -> 0.575 | F11: =AM11+角色!M11+中间!$L$20 -> 420 | G11: =D11*(1+E11)+F11 -> 2143.2075 | H11: =角色!F11 -> 16483.2 | I11: =角色!N11+VLOOKUP($V11,弧盘!$A$2:$AF$51,弧盘!$J$1,FALSE)+VLOOKUP($X11,卡带!$A$2:$V$14,卡带!$D$1,FALSE)+IF($AB11="生命",中间!$M$8,0)+IF($AD11="生命",$AF11*$AC11%,0)+AN11 -> 0 | J11: =AO11+角色!O11+中间!$L$21 -> 5200 | K11: =H11*(1+I11)+J11 -> 21683.2 | L11: =角色!H11 -> 909 | M11: =角色!P11+VLOOKUP($V11,弧盘!$A$2:$AF$51,弧盘!$K$1,FALSE)+VLOOKUP($X11,卡带!$A$2:$V$14,卡带!$E$1,FALSE)+IF($AB11="防御",中间!$M$9,0)+IF($AD11="防御",$AF11*$AC11%,0)+AR11 -> 0 | N11: =AQ11+角色!Q11 -> 0 | O11: =L11*(1+M11)+N11 -> 909 | P11: =角色!J11+VLOOKUP($V11,弧盘!$A$2:$AF$51,弧盘!$G$1,FALSE)+IF(AB11="暴击",中间!$M$3,0)+AH11+IF($AD11="暴击",$AC11%*$AF11,0) -> 0.15 | Q11: =角色!K11+VLOOKUP($V11,弧盘!$A$2:$AF$51,弧盘!$H$1,FALSE)+IF(AB11="暴伤",中间!$M$4,0)+IF($AD11="暴伤",$AC11%*$AF11,0)+AI11 -> 0.7 | R11: =角色!X11+VLOOKUP($X11,卡带!A$3:B$15,卡带!$B$1,FALSE)+IF(AB11="属伤",中间!$M$2,0)+IF($AD11="属伤",$AC11%*$AF11,0) -> 0.48 | S11: =角色!T11+VLOOKUP($V11,弧盘!$A$2:$AF$51,弧盘!$L$1,FALSE)+VLOOKUP($X11,卡带!A$3:F$15,卡带!$F$1,FALSE)+IF($AD11="充能",$AC11%*$AF11,0) -> 0.12 | T11: =角色!U11+VLOOKUP($V11,弧盘!$A$2:$AF$51,弧盘!M$1,FALSE)+VLOOKUP($X11,卡带!$A$2:$V$14,卡带!G$1,FALSE)+IF($AB11="精通",中间!$M$5,0)+IF($AD11="精通",$AC11%*$AF11,0)+AJ11 -> 270 | U11: =角色!V11+VLOOKUP($V11,弧盘!$A$2:$AF$51,弧盘!N$1,FALSE)+VLOOKUP($X11,卡带!$A$2:$V$14,卡带!H$1,FALSE)+IF($AB11="倾陷",中间!$M$6,0)+AK11 -> 0 | V11: 好狗狗走四方 | W11: =IFERROR(VLOOKUP(V11,弧盘!$A$2:O60,弧盘!$O$1,FALSE),"") -> 18充能；Q后全队10%攻击，控住额外6%，20秒 | X11: 音速蓝刺猬 | Y11: =IFERROR(VLOOKUP(X11,卡带!$A$2:$J$14,卡带!$J$1,FALSE),"") -> 12充能；Q后全队15%攻击，10秒 | Z11: 10 | AA11: =POWER(1.08,Z11-1+IF(AY11,1,0)) -> 1.9990046 | AB11: 精通 | AC11: 8 | AD11: 属伤 | AE11: =AC11&AD11 -> 8属伤 | AF11: 6 | AG11: 0.15 | AH11: 0.1 | AI11: 0.2 | AJ11: 90 | AL11: 0.125 | AX11: =COUNTIF($AR11:$AW11,TRUE) -> 0 | AY11: =AX11>2 -> FALSE | AZ11: =AX11>5 -> FALSE
A12: 阿德勒 | B12: =角色!B12 -> 咒 | C12: 聚合 | D12: =角色!D12+VLOOKUP($V12,弧盘!$A$2:$C$51,弧盘!$B$1,FALSE) -> 832.25 | E12: =角色!L12+VLOOKUP($V12,弧盘!$A$2:$AF$51,弧盘!$I$1,FALSE)+VLOOKUP($X12,卡带!$A$2:$V$14,卡带!$C$1,FALSE)+IF($AB12="攻击",中间!$M$7,0)+IF($AD12="攻击",$AF12*$AC12%,0)+AP12 -> 0.2625 | F12: =AM12+角色!M12+中间!$L$20 -> 420 | G12: =D12*(1+E12)+F12 -> 1470.7156 | H12: =角色!F12 -> 14301.6 | I12: =角色!N12+VLOOKUP($V12,弧盘!$A$2:$AF$51,弧盘!$J$1,FALSE)+VLOOKUP($X12,卡带!$A$2:$V$14,卡带!$D$1,FALSE)+IF($AB12="生命",中间!$M$8,0)+IF($AD12="生命",$AF12*$AC12%,0)+AN12 -> 0 | J12: =AO12+角色!O12+中间!$L$21 -> 5200 | K12: =H12*(1+I12)+J12 -> 19501.6 | L12: =角色!H12 -> 993.84 | M12: =角色!P12+VLOOKUP($V12,弧盘!$A$2:$AF$51,弧盘!$K$1,FALSE)+VLOOKUP($X12,卡带!$A$2:$V$14,卡带!$E$1,FALSE)+IF($AB12="防御",中间!$M$9,0)+IF($AD12="防御",$AF12*$AC12%,0)+AR12 -> 2.395 | N12: =AQ12+角色!Q12 -> 0 | O12: =L12*(1+M12)+N12 -> 3374.0868 | P12: =角色!J12+VLOOKUP($V12,弧盘!$A$2:$AF$51,弧盘!$G$1,FALSE)+IF(AB12="暴击",中间!$M$3,0)+AH12+IF($AD12="暴击",$AC12%*$AF12,0) -> 0.2 | Q12: =角色!K12+VLOOKUP($V12,弧盘!$A$2:$AF$51,弧盘!$H$1,FALSE)+IF(AB12="暴伤",中间!$M$4,0)+IF($AD12="暴伤",$AC12%*$AF12,0)+AI12 -> 0.8 | R12: =角色!X12+VLOOKUP($X12,卡带!A$3:B$15,卡带!$B$1,FALSE)+IF(AB12="属伤",中间!$M$2,0)+IF($AD12="属伤",$AC12%*$AF12,0) -> 0.375 | S12: =角色!T12+VLOOKUP($V12,弧盘!$A$2:$AF$51,弧盘!$L$1,FALSE)+VLOOKUP($X12,卡带!A$3:F$15,卡带!$F$1,FALSE)+IF($AD12="充能",$AC12%*$AF12,0) -> 0 | T12: =角色!U12+VLOOKUP($V12,弧盘!$A$2:$AF$51,弧盘!M$1,FALSE)+VLOOKUP($X12,卡带!$A$2:$V$14,卡带!G$1,FALSE)+IF($AB12="精通",中间!$M$5,0)+IF($AD12="精通",$AC12%*$AF12,0)+AJ12 -> 0 | U12: =角色!V12+VLOOKUP($V12,弧盘!$A$2:$AF$51,弧盘!N$1,FALSE)+VLOOKUP($X12,卡带!$A$2:$V$14,卡带!H$1,FALSE)+IF($AB12="倾陷",中间!$M$6,0)+AK12 -> 0 | V12: 勿忘伞 | W12: =IFERROR(VLOOKUP(V12,弧盘!$A$2:O61,弧盘!$O$1,FALSE),"") -> 18生命；18护盾强度 | X12: 守卫王国 | Y12: =IFERROR(VLOOKUP(X12,卡带!$A$2:$J$14,卡带!$J$1,FALSE),"") -> 15防御；20%护盾强效 | Z12: 10 | AA12: =POWER(1.08,Z12-1+IF(AY12,1,0)) -> 2.158925 | AB12: 属伤 | AC12: 12 | AD12: 防御 | AE12: =AC12&AD12 -> 12防御 | AF12: 6 | AG12: 0.15 | AH12: 0.15 | AI12: 0.3 | AP12: =1.75%*15 -> 0.2625 | AR12: TRUE | AS12: TRUE | AT12: TRUE | AU12: TRUE | AV12: TRUE | AW12: TRUE | AX12: =COUNTIF($AR12:$AW12,TRUE) -> 6 | AY12: =AX12>2 -> TRUE | AZ12: =AX12>5 -> TRUE
A13: 安魂曲 | B13: =角色!B13 -> 暗 | C13: 液态 | D13: =角色!D13+VLOOKUP($V13,弧盘!$A$2:$C$51,弧盘!$B$1,FALSE) -> 1206 | E13: =角色!L13+VLOOKUP($V13,弧盘!$A$2:$AF$51,弧盘!$I$1,FALSE)+VLOOKUP($X13,卡带!$A$2:$V$14,卡带!$C$1,FALSE)+IF($AB13="攻击",中间!$M$7,0)+IF($AD13="攻击",$AF13*$AC13%,0)+AL13 -> 0.1875 | F13: =AM13+角色!M13+中间!$L$20 -> 620 | G13: =D13*(1+E13)+F13 -> 2052.125 | H13: =角色!F13 -> 15998.4 | I13: =角色!N13+VLOOKUP($V13,弧盘!$A$2:$AF$51,弧盘!$J$1,FALSE)+VLOOKUP($X13,卡带!$A$2:$V$14,卡带!$D$1,FALSE)+IF($AB13="生命",中间!$M$8,0)+IF($AD13="生命",$AF13*$AC13%,0)+AN13 -> 0 | J13: =AO13+角色!O13+中间!$L$21 -> 5200 | K13: =H13*(1+I13)+J13 -> 21198.4 | L13: =角色!H13 -> 909 | M13: =角色!P13+VLOOKUP($V13,弧盘!$A$2:$AF$51,弧盘!$K$1,FALSE)+VLOOKUP($X13,卡带!$A$2:$V$14,卡带!$E$1,FALSE)+IF($AB13="防御",中间!$M$9,0)+IF($AD13="防御",$AF13*$AC13%,0)+AR13 -> 0 | N13: =AQ13+角色!Q13 -> 0 | O13: =L13*(1+M13)+N13 -> 909 | P13: =角色!J13+VLOOKUP($V13,弧盘!$A$2:$AF$51,弧盘!$G$1,FALSE)+IF(AB13="暴击",中间!$M$3,0)+AH13+IF($AD13="暴击",$AC13%*$AF13,0) -> 0.39 | Q13: =角色!K13+VLOOKUP($V13,弧盘!$A$2:$AF$51,弧盘!$H$1,FALSE)+IF(AB13="暴伤",中间!$M$4,0)+IF($AD13="暴伤",$AC13%*$AF13,0)+AI13 -> 0.8 | R13: =角色!X13+VLOOKUP($X13,卡带!A$3:B$15,卡带!$B$1,FALSE)+IF(AB13="属伤",中间!$M$2,0)+IF($AD13="属伤",$AC13%*$AF13,0) -> 0.875 | S13: =角色!T13+VLOOKUP($V13,弧盘!$A$2:$AF$51,弧盘!$L$1,FALSE)+VLOOKUP($X13,卡带!A$3:F$15,卡带!$F$1,FALSE)+IF($AD13="充能",$AC13%*$AF13,0) -> 0 | T13: =角色!U13+VLOOKUP($V13,弧盘!$A$2:$AF$51,弧盘!M$1,FALSE)+VLOOKUP($X13,卡带!$A$2:$V$14,卡带!G$1,FALSE)+IF($AB13="精通",中间!$M$5,0)+IF($AD13="精通",$AC13%*$AF13,0)+AJ13 -> 0 | U13: =角色!V13+VLOOKUP($V13,弧盘!$A$2:$AF$51,弧盘!N$1,FALSE)+VLOOKUP($X13,卡带!$A$2:$V$14,卡带!H$1,FALSE)+IF($AB13="倾陷",中间!$M$6,0)+AK13 -> 0 | V13: 「最后一朵玫瑰」 | W13: =IFERROR(VLOOKUP(V13,弧盘!$A$2:O62,弧盘!$O$1,FALSE),"") -> 14攻击；叠层60暴伤；倾陷延时3s | X13: 迪亚波罗斯 | Y13: =IFERROR(VLOOKUP(X13,卡带!$A$2:$J$14,卡带!$J$1,FALSE),"") -> 10暗伤；无视12抗性，触发暗反应后翻倍，20秒 | Z13: 10 | AA13: =POWER(1.08,Z13-1+IF(AY13,1,0)) -> 1.9990046 | AB13: 属伤 | AC13: 10 | AD13: 属伤 | AE13: =AC13&AD13 -> 10属伤 | AF13: 4 | AG13: 0.15 | AH13: 0.1 | AI13: 0.3 | AL13: 0.1875 | AW13: TRUE | AX13: =COUNTIF($AR13:$AW13,TRUE) -> 1 | AY13: =AX13>2 -> FALSE | AZ13: =AX13>5 -> FALSE
A14: 达芙蒂尔 | B14: =角色!B14 -> 暗 | C14: 液态 | D14: =角色!D14+VLOOKUP($V14,弧盘!$A$2:$C$51,弧盘!$B$1,FALSE) -> 1213.95 | E14: =角色!L14+VLOOKUP($V14,弧盘!$A$2:$AF$51,弧盘!$I$1,FALSE)+VLOOKUP($X14,卡带!$A$2:$V$14,卡带!$C$1,FALSE)+IF($AB14="攻击",中间!$M$7,0)+IF($AD14="攻击",$AF14*$AC14%,0)+AL14 -> 0.425 | F14: =AM14+角色!M14+中间!$L$20 -> 420 | G14: =D14*(1+E14)+F14 -> 2149.8787 | H14: =角色!F14 -> 16180.2 | I14: =角色!N14+VLOOKUP($V14,弧盘!$A$2:$AF$51,弧盘!$J$1,FALSE)+VLOOKUP($X14,卡带!$A$2:$V$14,卡带!$D$1,FALSE)+IF($AB14="生命",中间!$M$8,0)+IF($AD14="生命",$AF14*$AC14%,0)+AN14 -> 0 | J14: =AO14+角色!O14+中间!$L$21 -> 5200 | K14: =H14*(1+I14)+J14 -> 21380.2 | L14: =角色!H14 -> 872.64 | M14: =角色!P14+VLOOKUP($V14,弧盘!$A$2:$AF$51,弧盘!$K$1,FALSE)+VLOOKUP($X14,卡带!$A$2:$V$14,卡带!$E$1,FALSE)+IF($AB14="防御",中间!$M$9,0)+IF($AD14="防御",$AF14*$AC14%,0)+AR14 -> 0 | N14: =AQ14+角色!Q14 -> 0 | O14: =L14*(1+M14)+N14 -> 872.64 | P14: =角色!J14+VLOOKUP($V14,弧盘!$A$2:$AF$51,弧盘!$G$1,FALSE)+IF(AB14="暴击",中间!$M$3,0)+AH14+IF($AD14="暴击",$AC14%*$AF14,0) -> 0.15 | Q14: =角色!K14+VLOOKUP($V14,弧盘!$A$2:$AF$51,弧盘!$H$1,FALSE)+IF(AB14="暴伤",中间!$M$4,0)+IF($AD14="暴伤",$AC14%*$AF14,0)+AI14 -> 0.7 | R14: =角色!X14+VLOOKUP($X14,卡带!A$3:B$15,卡带!$B$1,FALSE)+IF(AB14="属伤",中间!$M$2,0)+IF($AD14="属伤",$AC14%*$AF14,0) -> 0.875 | S14: =角色!T14+VLOOKUP($V14,弧盘!$A$2:$AF$51,弧盘!$L$1,FALSE)+VLOOKUP($X14,卡带!A$3:F$15,卡带!$F$1,FALSE)+IF($AD14="充能",$AC14%*$AF14,0) -> 0 | T14: =角色!U14+VLOOKUP($V14,弧盘!$A$2:$AF$51,弧盘!M$1,FALSE)+VLOOKUP($X14,卡带!$A$2:$V$14,卡带!G$1,FALSE)+IF($AB14="精通",中间!$M$5,0)+IF($AD14="精通",$AC14%*$AF14,0)+AJ14 -> 30 | U14: =角色!V14+VLOOKUP($V14,弧盘!$A$2:$AF$51,弧盘!N$1,FALSE)+VLOOKUP($X14,卡带!$A$2:$V$14,卡带!H$1,FALSE)+IF($AB14="倾陷",中间!$M$6,0)+AK14 -> 60 | V14: 漆黑青春妄想 | W14: =IFERROR(VLOOKUP(V14,弧盘!$A$2:O63,弧盘!$O$1,FALSE),"") -> 60倾陷；调弧：20暗伤、倾陷200%倍率 | X14: 迪亚波罗斯 | Y14: =IFERROR(VLOOKUP(X14,卡带!$A$2:$J$14,卡带!$J$1,FALSE),"") -> 10暗伤；无视12抗性，触发暗反应后翻倍，20秒 | Z14: 10 | AA14: =POWER(1.08,Z14-1+IF(AY14,1,0)) -> 1.9990046 | AB14: 属伤 | AC14: 10 | AD14: 属伤 | AE14: =AC14&AD14 -> 10属伤 | AF14: 4 | AG14: 0.15 | AH14: 0.1 | AI14: 0.2 | AJ14: 30 | AK14: 60 | AL14: 0.125 | AT14: TRUE | AX14: =COUNTIF($AR14:$AW14,TRUE) -> 1 | AY14: =AX14>2 -> FALSE | AZ14: =AX14>5 -> FALSE
A15: 法帝娅 | B15: =角色!B15 -> 魂 | C15: 聚合 | D15: =角色!D15+VLOOKUP($V15,弧盘!$A$2:$C$51,弧盘!$B$1,FALSE) -> 1020.25 | E15: =角色!L15+VLOOKUP($V15,弧盘!$A$2:$AF$51,弧盘!$I$1,FALSE)+VLOOKUP($X15,卡带!$A$2:$V$14,卡带!$C$1,FALSE)+IF($AB15="攻击",中间!$M$7,0)+IF($AD15="攻击",$AF15*$AC15%,0)+AL15 -> 0 | F15: =AM15+角色!M15+中间!$L$20 -> 420 | G15: =D15*(1+E15)+F15 -> 1440.25 | H15: =角色!F15 -> 17089.2 | I15: =角色!N15+VLOOKUP($V15,弧盘!$A$2:$AF$51,弧盘!$J$1,FALSE)+VLOOKUP($X15,卡带!$A$2:$V$14,卡带!$D$1,FALSE)+IF($AB15="生命",中间!$M$8,0)+IF($AD15="生命",$AF15*$AC15%,0)+AN15 -> 0.8975 | J15: =AO15+角色!O15+中间!$L$21 -> 5200 | K15: =H15*(1+I15)+J15 -> 37626.757 | L15: =角色!H15 -> 909 | M15: =角色!P15+VLOOKUP($V15,弧盘!$A$2:$AF$51,弧盘!$K$1,FALSE)+VLOOKUP($X15,卡带!$A$2:$V$14,卡带!$E$1,FALSE)+IF($AB15="防御",中间!$M$9,0)+IF($AD15="防御",$AF15*$AC15%,0)+AR15 -> 0 | N15: =AQ15+角色!Q15 -> 0 | O15: =L15*(1+M15)+N15 -> 909 | P15: =角色!J15+VLOOKUP($V15,弧盘!$A$2:$AF$51,弧盘!$G$1,FALSE)+IF(AB15="暴击",中间!$M$3,0)+AH15+IF($AD15="暴击",$AC15%*$AF15,0) -> 0.15 | Q15: =角色!K15+VLOOKUP($V15,弧盘!$A$2:$AF$51,弧盘!$H$1,FALSE)+IF(AB15="暴伤",中间!$M$4,0)+IF($AD15="暴伤",$AC15%*$AF15,0)+AI15 -> 0.7 | R15: =角色!X15+VLOOKUP($X15,卡带!A$3:B$15,卡带!$B$1,FALSE)+IF(AB15="属伤",中间!$M$2,0)+IF($AD15="属伤",$AC15%*$AF15,0) -> 0 | S15: =角色!T15+VLOOKUP($V15,弧盘!$A$2:$AF$51,弧盘!$L$1,FALSE)+VLOOKUP($X15,卡带!A$3:F$15,卡带!$F$1,FALSE)+IF($AD15="充能",$AC15%*$AF15,0) -> 0.12 | T15: =角色!U15+VLOOKUP($V15,弧盘!$A$2:$AF$51,弧盘!M$1,FALSE)+VLOOKUP($X15,卡带!$A$2:$V$14,卡带!G$1,FALSE)+IF($AB15="精通",中间!$M$5,0)+IF($AD15="精通",$AC15%*$AF15,0)+AJ15 -> 0 | U15: =角色!V15+VLOOKUP($V15,弧盘!$A$2:$AF$51,弧盘!N$1,FALSE)+VLOOKUP($X15,卡带!$A$2:$V$14,卡带!H$1,FALSE)+IF($AB15="倾陷",中间!$M$6,0)+AK15 -> 270 | V15: 永恒圆舞曲 | W15: =IFERROR(VLOOKUP(V15,弧盘!$A$2:O64,弧盘!$O$1,FALSE),"") -> 25生命；Q后20潜意伤，10秒 | X15: 音速蓝刺猬 | Y15: =IFERROR(VLOOKUP(X15,卡带!$A$2:$J$14,卡带!$J$1,FALSE),"") -> 12充能；Q后全队15%攻击，10秒 | Z15: 10 | AA15: =POWER(1.08,Z15-1+IF(AY15,1,0)) -> 1.9990046 | AB15: 倾陷 | AC15: 6 | AD15: 生命 | AE15: =AC15&AD15 -> 6生命 | AF15: 6 | AG15: 0.15 | AH15: 0.1 | AI15: 0.2 | AK15: 90 | AN15: 0.125 | AX15: =COUNTIF($AR15:$AW15,TRUE) -> 0 | AY15: =AX15>2 -> FALSE | AZ15: =AX15>5 -> FALSE
A16: 哈尼娅 | B16: =角色!B16 -> 魂 | C16: 固态 | D16: =角色!D16+VLOOKUP($V16,弧盘!$A$2:$C$51,弧盘!$B$1,FALSE) -> 1004.9 | E16: =角色!L16+VLOOKUP($V16,弧盘!$A$2:$AF$51,弧盘!$I$1,FALSE)+VLOOKUP($X16,卡带!$A$2:$V$14,卡带!$C$1,FALSE)+IF($AB16="攻击",中间!$M$7,0)+IF($AD16="攻击",$AF16*$AC16%,0)+AL16 -> 1 | F16: =AM16+角色!M16+中间!$L$20 -> 420 | G16: =D16*(1+E16)+F16 -> 2429.8 | H16: =角色!F16 -> 13695.6 | I16: =角色!N16+VLOOKUP($V16,弧盘!$A$2:$AF$51,弧盘!$J$1,FALSE)+VLOOKUP($X16,卡带!$A$2:$V$14,卡带!$D$1,FALSE)+IF($AB16="生命",中间!$M$8,0)+IF($AD16="生命",$AF16*$AC16%,0)+AN16 -> 0 | J16: =AO16+角色!O16+中间!$L$21 -> 5200 | K16: =H16*(1+I16)+J16 -> 18895.6 | L16: =角色!H16 -> 848.4 | M16: =角色!P16+VLOOKUP($V16,弧盘!$A$2:$AF$51,弧盘!$K$1,FALSE)+VLOOKUP($X16,卡带!$A$2:$V$14,卡带!$E$1,FALSE)+IF($AB16="防御",中间!$M$9,0)+IF($AD16="防御",$AF16*$AC16%,0)+AR16 -> 1 | N16: =AQ16+角色!Q16 -> 0 | O16: =L16*(1+M16)+N16 -> 1696.8 | P16: =角色!J16+VLOOKUP($V16,弧盘!$A$2:$AF$51,弧盘!$G$1,FALSE)+IF(AB16="暴击",中间!$M$3,0)+AH16+IF($AD16="暴击",$AC16%*$AF16,0) -> 0.15 | Q16: =角色!K16+VLOOKUP($V16,弧盘!$A$2:$AF$51,弧盘!$H$1,FALSE)+IF(AB16="暴伤",中间!$M$4,0)+IF($AD16="暴伤",$AC16%*$AF16,0)+AI16 -> 0.7 | R16: =角色!X16+VLOOKUP($X16,卡带!A$3:B$15,卡带!$B$1,FALSE)+IF(AB16="属伤",中间!$M$2,0)+IF($AD16="属伤",$AC16%*$AF16,0) -> 0 | S16: =角色!T16+VLOOKUP($V16,弧盘!$A$2:$AF$51,弧盘!$L$1,FALSE)+VLOOKUP($X16,卡带!A$3:F$15,卡带!$F$1,FALSE)+IF($AD16="充能",$AC16%*$AF16,0) -> 0.12 | T16: =角色!U16+VLOOKUP($V16,弧盘!$A$2:$AF$51,弧盘!M$1,FALSE)+VLOOKUP($X16,卡带!$A$2:$V$14,卡带!G$1,FALSE)+IF($AB16="精通",中间!$M$5,0)+IF($AD16="精通",$AC16%*$AF16,0)+AJ16 -> 0 | U16: =角色!V16+VLOOKUP($V16,弧盘!$A$2:$AF$51,弧盘!N$1,FALSE)+VLOOKUP($X16,卡带!$A$2:$V$14,卡带!H$1,FALSE)+IF($AB16="倾陷",中间!$M$6,0)+AK16 -> 270 | V16: 引爆全场 | W16: =IFERROR(VLOOKUP(V16,弧盘!$A$2:O65,弧盘!$O$1,FALSE),"") -> 12-32%魂伤 | X16: 音速蓝刺猬 | Y16: =IFERROR(VLOOKUP(X16,卡带!$A$2:$J$14,卡带!$J$1,FALSE),"") -> 12充能；Q后全队15%攻击，10秒 | Z16: 10 | AA16: =POWER(1.08,Z16-1+IF(AY16,1,0)) -> 2.158925 | AB16: 倾陷 | AC16: 10 | AD16: 攻击 | AE16: =AC16&AD16 -> 10攻击 | AF16: 6 | AG16: 0.15 | AH16: 0.1 | AI16: 0.2 | AK16: 90 | AL16: 0.125 | AR16: TRUE | AS16: TRUE | AT16: TRUE | AU16: TRUE | AV16: TRUE | AW16: TRUE | AX16: =COUNTIF($AR16:$AW16,TRUE) -> 6 | AY16: =AX16>2 -> TRUE | AZ16: =AX16>5 -> TRUE
A17: 哈索尔 | B17: =角色!B17 -> 相 | C17: 等离子 | D17: =角色!D17+VLOOKUP($V17,弧盘!$A$2:$C$51,弧盘!$B$1,FALSE) -> 1309.95 | E17: =角色!L17+VLOOKUP($V17,弧盘!$A$2:$AF$51,弧盘!$I$1,FALSE)+VLOOKUP($X17,卡带!$A$2:$V$14,卡带!$C$1,FALSE)+IF($AB17="攻击",中间!$M$7,0)+IF($AD17="攻击",$AF17*$AC17%,0)+AL17 -> 0.5875 | F17: =AM17+角色!M17+中间!$L$20 -> 420 | G17: =D17*(1+E17)+F17 -> 2499.5456 | H17: =角色!F17 -> 15998.4 | I17: =角色!N17+VLOOKUP($V17,弧盘!$A$2:$AF$51,弧盘!$J$1,FALSE)+VLOOKUP($X17,卡带!$A$2:$V$14,卡带!$D$1,FALSE)+IF($AB17="生命",中间!$M$8,0)+IF($AD17="生命",$AF17*$AC17%,0)+AN17 -> 0 | J17: =AO17+角色!O17+中间!$L$21 -> 5200 | K17: =H17*(1+I17)+J17 -> 21198.4 | L17: =角色!H17 -> 884.76 | M17: =角色!P17+VLOOKUP($V17,弧盘!$A$2:$AF$51,弧盘!$K$1,FALSE)+VLOOKUP($X17,卡带!$A$2:$V$14,卡带!$E$1,FALSE)+IF($AB17="防御",中间!$M$9,0)+IF($AD17="防御",$AF17*$AC17%,0)+AR17 -> 0 | N17: =AQ17+角色!Q17 -> 0 | O17: =L17*(1+M17)+N17 -> 884.76 | P17: =角色!J17+VLOOKUP($V17,弧盘!$A$2:$AF$51,弧盘!$G$1,FALSE)+IF(AB17="暴击",中间!$M$3,0)+AH17+IF($AD17="暴击",$AC17%*$AF17,0) -> 0.5 | Q17: =角色!K17+VLOOKUP($V17,弧盘!$A$2:$AF$51,弧盘!$H$1,FALSE)+IF(AB17="暴伤",中间!$M$4,0)+IF($AD17="暴伤",$AC17%*$AF17,0)+AI17 -> 1.04 | R17: =角色!X17+VLOOKUP($X17,卡带!A$3:B$15,卡带!$B$1,FALSE)+IF(AB17="属伤",中间!$M$2,0)+IF($AD17="属伤",$AC17%*$AF17,0) -> 0.1 | S17: =角色!T17+VLOOKUP($V17,弧盘!$A$2:$AF$51,弧盘!$L$1,FALSE)+VLOOKUP($X17,卡带!A$3:F$15,卡带!$F$1,FALSE)+IF($AD17="充能",$AC17%*$AF17,0) -> 0 | T17: =角色!U17+VLOOKUP($V17,弧盘!$A$2:$AF$51,弧盘!M$1,FALSE)+VLOOKUP($X17,卡带!$A$2:$V$14,卡带!G$1,FALSE)+IF($AB17="精通",中间!$M$5,0)+IF($AD17="精通",$AC17%*$AF17,0)+AJ17 -> 0 | U17: =角色!V17+VLOOKUP($V17,弧盘!$A$2:$AF$51,弧盘!N$1,FALSE)+VLOOKUP($X17,卡带!$A$2:$V$14,卡带!H$1,FALSE)+IF($AB17="倾陷",中间!$M$6,0)+AK17 -> 0 | V17: 焰魂狂飙 | W17: =IFERROR(VLOOKUP(V17,弧盘!$A$2:O65,弧盘!$O$1,FALSE),"") -> Q后22.5E伤，每次额外提升15 | X17: 街头拳王 | Y17: =IFERROR(VLOOKUP(X17,卡带!$A$2:$J$14,卡带!$J$1,FALSE),"") -> 10相伤；相反应28暴击，15秒 | Z17: 10 | AA17: =POWER(1.08,Z17-1+IF(AY17,1,0)) -> 1.9990046 | AB17: 暴击 | AC17: 10 | AD17: 攻击 | AE17: =AC17&AD17 -> 10攻击 | AF17: 4 | AG17: 0.15 | AH17: 0.15 | AI17: 0.3 | AL17: =15*1.25% -> 0.1875 | AX17: =COUNTIF($AR17:$AW17,TRUE) -> 0 | AY17: =AX17>2 -> FALSE | AZ17: =AX17>5 -> FALSE
A18: 翳 | B18: =角色!B18 -> 相 | C18: 气态 | D18: =角色!D18+VLOOKUP($V18,弧盘!$A$2:$C$51,弧盘!$B$1,FALSE) -> 1031.5 | E18: =角色!L18+VLOOKUP($V18,弧盘!$A$2:$AF$51,弧盘!$I$1,FALSE)+VLOOKUP($X18,卡带!$A$2:$V$14,卡带!$C$1,FALSE)+IF($AB18="攻击",中间!$M$7,0)+IF($AD18="攻击",$AF18*$AC18%,0)+AL18 -> 0.5875 | F18: =AM18+角色!M18+中间!$L$20 -> 420 | G18: =D18*(1+E18)+F18 -> 2057.5062 | H18: =角色!F18 -> 13332 | I18: =角色!N18+VLOOKUP($V18,弧盘!$A$2:$AF$51,弧盘!$J$1,FALSE)+VLOOKUP($X18,卡带!$A$2:$V$14,卡带!$D$1,FALSE)+IF($AB18="生命",中间!$M$8,0)+IF($AD18="生命",$AF18*$AC18%,0)+AN18 -> 0 | J18: =AO18+角色!O18+中间!$L$21 -> 5200 | K18: =H18*(1+I18)+J18 -> 18532 | L18: =角色!H18 -> 666.6 | M18: =角色!P18+VLOOKUP($V18,弧盘!$A$2:$AF$51,弧盘!$K$1,FALSE)+VLOOKUP($X18,卡带!$A$2:$V$14,卡带!$E$1,FALSE)+IF($AB18="防御",中间!$M$9,0)+IF($AD18="防御",$AF18*$AC18%,0)+AR18 -> 1 | N18: =AQ18+角色!Q18 -> 0 | O18: =L18*(1+M18)+N18 -> 1333.2 | P18: =角色!J18+VLOOKUP($V18,弧盘!$A$2:$AF$51,弧盘!$G$1,FALSE)+IF(AB18="暴击",中间!$M$3,0)+AH18+IF($AD18="暴击",$AC18%*$AF18,0) -> 0.6 | Q18: =角色!K18+VLOOKUP($V18,弧盘!$A$2:$AF$51,弧盘!$H$1,FALSE)+IF(AB18="暴伤",中间!$M$4,0)+IF($AD18="暴伤",$AC18%*$AF18,0)+AI18 -> 1.2 | R18: =角色!X18+VLOOKUP($X18,卡带!A$3:B$15,卡带!$B$1,FALSE)+IF(AB18="属伤",中间!$M$2,0)+IF($AD18="属伤",$AC18%*$AF18,0) -> 0.1 | S18: =角色!T18+VLOOKUP($V18,弧盘!$A$2:$AF$51,弧盘!$L$1,FALSE)+VLOOKUP($X18,卡带!A$3:F$15,卡带!$F$1,FALSE)+IF($AD18="充能",$AC18%*$AF18,0) -> 0 | T18: =角色!U18+VLOOKUP($V18,弧盘!$A$2:$AF$51,弧盘!M$1,FALSE)+VLOOKUP($X18,卡带!$A$2:$V$14,卡带!G$1,FALSE)+IF($AB18="精通",中间!$M$5,0)+IF($AD18="精通",$AC18%*$AF18,0)+AJ18 -> 0 | U18: =角色!V18+VLOOKUP($V18,弧盘!$A$2:$AF$51,弧盘!N$1,FALSE)+VLOOKUP($X18,卡带!$A$2:$V$14,卡带!H$1,FALSE)+IF($AB18="倾陷",中间!$M$6,0)+AK18 -> 0 | V18: 当心头顶 | W18: =IFERROR(VLOOKUP(V18,弧盘!$A$2:O66,弧盘!$O$1,FALSE),"") -> E后18%攻击力，相环合敌人下，额外18%相伤，持续15秒 | X18: 街头拳王 | Y18: =IFERROR(VLOOKUP(X18,卡带!$A$2:$J$14,卡带!$J$1,FALSE),"") -> 10相伤；相反应28暴击，15秒 | Z18: 10 | AA18: =POWER(1.08,Z18-1+IF(AY18,1,0)) -> 2.158925 | AB18: 暴击 | AC18: 10 | AD18: 攻击 | AE18: =AC18&AD18 -> 10攻击 | AF18: 4 | AG18: 0.15 | AH18: 0.15 | AI18: 0.3 | AL18: =15*1.25% -> 0.1875 | AR18: TRUE | AS18: TRUE | AT18: TRUE | AU18: TRUE | AV18: TRUE | AW18: TRUE | AX18: =COUNTIF($AR18:$AW18,TRUE) -> 6 | AY18: =AX18>2 -> TRUE | AZ18: =AX18>5 -> TRUE

Sheet 增益
A1: 增益 | B1: 易伤 | C1: 减防 | D1: 减抗 | E1: 攻击% | F1: 攻击 | G1: 生命% | H1: 生命 | I1: 防御% | J1: 防御 | K1: 精通 | L1: 倾陷效率 | M1: 充能效率 | N1: 充能分享 | O1: 增伤 | P1: 暴击 | Q1: 暴伤
A3: 小吱收集癖 | M3: 0.2 | N3: -0.6
A4: 主角E觉加攻 | E4: 0.1
A5: 娜娜莉E暴伤 | Q5: 0.3
A6: 哈索尔Q加攻 | E6: 0.9
A7: 哈尼娅Q期间 | O7: =IF(配装!AV16,30%,0) -> 0.3 | P7: =IF(配装!AT16,20%,0) -> 0.2
A8: 阿德勒Q后E | O8: =IF(配装!$AR$12,IF(配装!$AS$12,3%,2%)*20,0) -> 0.6
A9: 阿德勒6命Q后E | O9: =IF(配装!$AR$12,IF(配装!$AS$12,3%,2%)*20,0)+10% -> 0.7
A10: 薄荷C觉反应加攻 | E10: 0.15
A11: 薄荷F觉低血增伤 | O11: 0.15
A13: 主角6命全队加攻 | E13: 0.1
A14: 早雾DOT增伤 | B14: =25%*云配队!H13 -> 0
A15: 早雾天赋 | F15: =IF(配装!AU11,60%,30%)*配装!D11 -> 328.23
A16: 哈尼娅E | F16: =22%*配装!$D$16 -> 221.078
A17: 哈尼娅Q | F17: =22%*配装!$D$16 -> 221.078 | Q17: =IF(配装!AZ16,12%,0) -> 0.12
A18: 哈尼娅黯星 | F18: =16%*配装!$D$16 -> 160.784
A19: 阿德勒浊燃-平均 | D19: 0.0333 | L19: 0.0333
A20: 阿德勒6命咒伤 | O20: 0.1
A21: 翳D觉附着伤 | O21: 0.15
A22: 翳6命相抗 | D22: 0.06 | O22: 0.15
A24: 光套减防 | C24: 0.25
A25: 暗套二级减抗 | D25: 0.12
A26: 暗套环合减抗 | D26: 0.24
A27: 音速蓝刺猬 | E27: 0.15
A29: 好狗狗走四方基础 | E29: 0.1
A30: 好狗狗走四方控住 | E30: 0.16
A31: 引爆全场加攻 | E31: =(10%+18%)/2 -> 0.14
A32: 引爆全场最低 | E32: 0.1
A33: 挂心难加攻 | E33: 0.16
A34: 行进时间外开Q | C34: 0.12 | Q34: 0.45
A35: 预备备开Q普攻 | O35: =15%+IF(中间!$N$2,10%,0) -> 0.25
A36: 预备备开Q非普攻 | O36: =IF(中间!$N$2,10%,0) -> 0.1
A37: 焰魂狂飙1层 | O37: =22.5%+15%*1 -> 0.375
A38: 焰魂狂飙2层 | O38: =22.5%+15%*2 -> 0.525
A39: 漆黑青春妄想调弧 | O39: 0.2

Sheet 中间
A1: 伤害类型 | D1: 总伤害 | E1: 总倾陷 | F1: 总源质 | G1: 总环合 | H1: 动作占比 | K1: 主词条 | L1: 紫品质 | M1: 金品质 | N1: 对BOSS | O1: 反应 | P1: 增幅 | Q1: 系数 | S1: 额外标签 | T1: 选项 | U1: 参与反应 | V1: 增幅精通 | W1: 弱点 | X1: 反应
A2: 援护 | B2: 角色1 | C2: =云配队!AF4 -> 娜娜莉 | D2: =SUMIF(计算!$1:$1,"s",计算!4:4) -> 235058.87 | E2: =SUMIF(计算!$1:$1,"q",计算!4:4) -> 16.523 | F2: =SUMIF(计算!$1:$1,"y",计算!4:4) -> 76.3986 | G2: =SUMIF(计算!$1:$1,"h",计算!4:4) -> 86.5 | H2: =云配队!F4 -> 娜娜莉 | I2: 首角色动作贡献占比 | K2: 属伤 | L2: 0.3 | M2: 0.375 | N2: =云配队!G13="BOSS" -> TRUE | U2: 精通贡献 | V2: 全队最高 | X2: 光 | Y2: 灵 | Z2: 咒 | AA2: 暗 | AB2: 魂 | AC2: 相
A3: E | B3: 角色2 | C3: =云配队!AF5 -> 主角 | D3: =SUMIF(计算!$1:$1,"s",计算!5:5) -> 49667.023 | E3: =SUMIF(计算!$1:$1,"q",计算!5:5) -> 5.301167 | F3: =SUMIF(计算!$1:$1,"y",计算!5:5) -> 90.672534 | G3: =SUMIF(计算!$1:$1,"h",计算!5:5) -> 100 | H3: {=_xlfn._xlws.FILTER(动作!$B$4:$B$113,动作!$A$4:$A$113=H2)} -> 援护 | I3: =SUMIF(计算!$2:$2,H3,计算!$4:$4) -> 0 | K3: 暴击 | L3: 0.24 | M3: 0.3 | O3: 延滞 | S3: 心灵 | T3: TRUE | U3: 连携 | V3: =云配队!F4 -> 娜娜莉 | W3: 光 | Y3: 创生 | AC3: 延滞
A4: Q | B4: 角色3 | C4: =云配队!AF6 -> 阿德勒 | D4: =SUMIF(计算!$1:$1,"s",计算!6:6) -> 35076.199 | E4: =SUMIF(计算!$1:$1,"q",计算!6:6) -> 8.65 | F4: =SUMIF(计算!$1:$1,"y",计算!6:6) -> 70.3594 | G4: =SUMIF(计算!$1:$1,"h",计算!6:6) -> 20.1 | H4: C觉追击 | I4: =SUMIF(计算!$2:$2,H4,计算!$4:$4) -> 36331.326 | K4: 暴伤 | L4: 0.48 | M4: 0.6 | O4: 创生 | S4: 附着 | V4: =云配队!F5 -> 主角 | W4: 灵 | X4: 创生 | Z4: 赋纹
A5: 普攻 | B5: 角色4 | C5: =云配队!AF7 -> 九原 | D5: =SUMIF(计算!$1:$1,"s",计算!7:7) -> 122780.92 | E5: =SUMIF(计算!$1:$1,"q",计算!7:7) -> 5.4 | F5: =SUMIF(计算!$1:$1,"y",计算!7:7) -> 140.3594 | G5: =SUMIF(计算!$1:$1,"h",计算!7:7) -> 11.802 | H5: 天赋追击 | I5: =SUMIF(计算!$2:$2,H5,计算!$4:$4) -> 0 | K5: 精通 | L5: 144 | M5: 180 | O5: 赋纹 | P5: TRUE | Q5: 0.2 | S5: 追击 | V5: =云配队!F6 -> 阿德勒 | W5: 咒 | Y5: 赋纹 | AA5: 浊燃
A6: 闪反 | C6: 创生 | D6: =SUMIF(计算!$1:$1,"s",计算!27:27) -> 222831.55 | H6: 5a | I6: =SUMIF(计算!$2:$2,H6,计算!$4:$4) -> 61453.635 | K6: 倾陷 | L6: 144 | M6: 180 | O6: 浊燃 | S6: DOT | V6: =云配队!F7 -> 九原 | W6: 暗 | Z6: 浊燃 | AB6: 黯星
A7: 下落 | C7: 浊燃 | D7: =SUMIF(计算!$1:$1,"s",计算!28:28) -> 0 | H7: 5a副手 | I7: =SUMIF(计算!$2:$2,H7,计算!$4:$4) -> 18156.134 | K7: 攻击 | L7: 0.3 | M7: 0.375 | O7: 黯星 | W7: 魂 | AA7: 黯星 | AC7: 侵染
A8: 无 | C8: 黯星 | D8: =SUMIF(计算!$1:$1,"s",计算!29:29) -> 0 | H8: 3z | I8: =SUMIF(计算!$2:$2,H8,计算!$4:$4) -> 0 | K8: 生命 | L8: 0.3 | M8: 0.375 | O8: 侵染 | P8: TRUE | Q8: =Q5 -> 0.2 | W8: 相 | X8: 延滞 | AB8: 侵染
C9: 失谐 | E9: =COUNTIF(云配队!J11:AC11,"失谐")*云配队!H9*20% -> 0 | H9: 3z副手 | I9: =SUMIF(计算!$2:$2,H9,计算!$4:$4) -> 0 | K9: 防御 | L9: 0.42 | M9: 0.525 | O9: 盈蓄
D10: =SUM(D2:D9) -> 665414.56 | E10: =SUM(E2:E9) -> 35.874167 | H10: 闪反 | I10: =SUMIF(计算!$2:$2,H10,计算!$4:$4) -> 30669.127 | K10: 治疗 | L10: 0.276 | M10: 0.345 | O10: 失谐
C11: 总时间 | D11: =SUMIF(计算!$1:$1,"t",计算!8:8) -> 15.8 | H11: 闪反副手 | I11: =SUMIF(计算!$2:$2,H11,计算!$4:$4) -> 9430.186
H12: 下落 | I12: =SUMIF(计算!$2:$2,H12,计算!$4:$4) -> 0 | S12: 等级 | U12: 创生 | V12: 浊燃 | W12: 黯星 | X12: 倾陷
H13: 下落副手 | I13: =SUMIF(计算!$2:$2,H13,计算!$4:$4) -> 0 | S13: 5 | T13: =S13/5 -> 1 | U13: 80 | V13: 20 | W13: 400 | X13: 78
H14: e | I14: =SUMIF(计算!$2:$2,H14,计算!$4:$4) -> 29433.813 | S14: 10 | T14: =S14/5 -> 2 | U14: 120 | V14: 35 | W14: 600 | X14: 88
H15: e副手 | I15: =SUMIF(计算!$2:$2,H15,计算!$4:$4) -> 0 | S15: 15 | T15: =S15/5 -> 3 | U15: 200 | V15: 60 | W15: 1000 | X15: 98
H16: q | I16: =SUMIF(计算!$2:$2,H16,计算!$4:$4) -> 49584.653 | S16: 20 | T16: =S16/5 -> 4 | U16: 300 | V16: 90 | W16: 1500 | X16: 108
I17: =SUMIF(计算!$2:$2,H17,计算!$4:$4) -> 0 | S17: 25 | T17: =S17/5 -> 5 | U17: 400 | V17: 120 | W17: 2000 | X17: 149
H18: 水位线 | S18: 30 | T18: =S18/5 -> 6 | U18: 600 | V18: 180 | W18: 3000 | X18: 198
K19: 驱动块主词条 | S19: 35 | T19: =S19/5 -> 7 | U19: 800 | V19: 240 | W19: 4000 | X19: 266
K20: 小攻击 | L20: =21*20 -> 420 | S20: 40 | T20: =S20/5 -> 8 | U20: 1000 | V20: 300 | W20: 5000 | X20: 356
A21: 动作轴 | B21: =云配队!F4 -> 娜娜莉 | C21: =云配队!F5 -> 主角 | D21: =云配队!F6 -> 阿德勒 | E21: =云配队!F7 -> 九原 | K21: 小生命 | L21: =260*20 -> 5200 | S21: 45 | T21: =S21/5 -> 9 | U21: 1700 | V21: 510 | W21: 8500 | X21: 478
S22: 50 | T22: =S22/5 -> 10 | U22: 2200 | V22: 660 | W22: 11000 | X22: 657
B23: {=IFERROR(_xlfn._xlws.FILTER(动作!$B$4:$B$113,动作!$A$4:$A$113=B21),"")} -> 援护 | C23: {=IFERROR(_xlfn._xlws.FILTER(动作!$B$4:$B$113,动作!$A$4:$A$113=C21),"")} -> 援护 | D23: {=IFERROR(_xlfn._xlws.FILTER(动作!$B$4:$B$113,动作!$A$4:$A$113=D21),"")} -> 援护 | E23: {=IFERROR(_xlfn._xlws.FILTER(动作!$B$4:$B$113,动作!$A$4:$A$113=E21),"")} -> 援护 | F23: {=IFERROR(_xlfn._xlws.FILTER(动作!$B$4:$B$113,动作!$A$4:$A$113=F21),"")} | G23: {=IFERROR(_xlfn._xlws.FILTER(动作!$B$4:$B$113,动作!$A$4:$A$113=G21),"")} | S23: 55 | T23: =S23/5 -> 11 | U23: 3600 | V23: 1080 | W23: 18000 | X23: 851
B24: C觉追击 | C24: e | D24: e | E24: 6枪 | S24: 60 | T24: =S24/5 -> 12 | U24: 5000 | V24: 1500 | W24: 25000 | X24: 1108
B25: 天赋追击 | C25: e额外 | D25: dot10跳 | E25: dot | K25: 弧盘副属性1级是满级的40% | S25: 65 | T25: =S25/5 -> 13 | U25: 6000 | V25: 1800 | W25: 30000 | X25: 1459
B26: 5a | C26: q | D26: q | E26: 清算 | K26: 卡带副词条等价10个驱动格子 | S26: 70 | T26: =S26/5 -> 14 | U26: 7000 | V26: 2100 | W26: 35000 | X26: 1834
B27: 5a副手 | E27: q清算 | K27: 驱动块一个格子 | O27: 三测 | S27: 75 | T27: =S27/5 -> 15 | U27: 8000 | V27: 2400 | W27: 40000 | X27: 2296
B28: 3z | E28: e | K28: 主攻击19.25（38/58/77） | N28: 16.75 | O28: =21*20 -> 420 | S28: 80 | T28: =S28/5 -> 16 | U28: 9000 | V28: 2700 | W28: 45000 | X28: 2772
B29: 3z副手 | E29: q | K29: 主生命256 | N29: 224 | O29: =260*20 -> 5200
B30: 闪反
B31: 闪反副手 | K31: 小攻击防御6.5（13/19/26） | O31: 8
B32: 下落 | K32: 小生命82.3（165/247/330） | O32: 100
B33: 下落副手 | K33: 大防御1.4% | O33: 0.0175
B34: e | K34: 大攻击生命1% | O34: 0.0125
B35: e副手 | K35: 伤害/暴击0.8% | O35: 0.01
B36: q | K36: 暴伤1.6% | O36: 0.02
K37: 倾陷精通4.8（10/14/19） | O37: 6
B38: 水位线

Sheet 动作
A1: =COLUMN() -> 1 | B1: =COLUMN() -> 2 | C1: =COLUMN() -> 3 | D1: =COLUMN() -> 4 | E1: =COLUMN() -> 5 | F1: =COLUMN() -> 6 | G1: =COLUMN() -> 7 | H1: =COLUMN() -> 8 | ... S1: =COLUMN() -> 19
A2: 角色 | B2: 动作 | C2: 伤害类型 | D2: 额外标签 | E2: 攻击倍率 | F2: 生命倍率 | G2: 防御倍率 | H2: 伤害值 | I2: 合轴时间 | J2: 回能 | K2: 环合 | L2: 倾陷 | M2: 说明 | N2: 返还能量 | O2: 暴击 | P2: 暴伤 | Q2: 增伤 | R2: 减防 | S2: 减抗
A3: 无 | B3: 无 | C3: 无
A4: 主角 | B4: 援护 | C4: 援护 | E4: 200 | I4: 1.3 | J4: 7.7 | L4: 2.5
A5: 主角 | B5: e | C5: E | E5: 300 | I5: 0.2 | J5: 8.801 | K5: 100 | L5: 1.8 | N5: =IF(配装!AS3,8,0) -> 8
A6: 主角 | B6: e额外 | C6: E | E6: =IF(配装!AW3,300,200)/配装!AA3 -> 92.638698 | R6: =IF(配装!AR3,75%,0) -> 0
A7: 主角 | B7: q | C7: Q | E7: 500 | L7: 1.501 | O7: =IF(配装!AT3,50%,0) -> 0.5
A8: 浔 | B8: 援护 | C8: 援护 | E8: 200 | I8: 1.3 | J8: 9.5 | L8: 2.5
A9: 浔 | B9: e | C9: E | E9: 300 | J9: 7.097 | K9: 11.794 | L9: 1.396
A10: 浔 | B10: q | C10: Q | E10: =800+550*2+200*2 -> 2300 | L10: 1.5
A11: 小吱 | B11: 援护 | C11: 援护 | E11: 200 | I11: 1.3 | J11: 8.6 | L11: 2.5
A12: 小吱 | B12: 5a | C12: 普攻 | E12: 325.7 | I12: 3.5 | J12: 16.3 | K12: 27.098 | L12: 3.301
A13: 小吱 | B13: 蓄力 | C13: 普攻 | E13: =77.5*2 -> 155 | J13: 7.8 | K13: 12.9 | L13: 1.6
A14: 小吱 | B14: 分支 | C14: 普攻 | E14: =96*2 -> 192 | J14: 9.6 | K14: 16 | L14: 1.9
A15: 小吱 | B15: 闪反 | C15: 闪反 | E15: 90 | I15: 1.3 | J15: 4.027 | K15: 6.672 | L15: 2.85
A16: 小吱 | B16: e1 | C16: E | E16: 59 | H16: =16000*IF(配装!$AR$5,1.25,1) -> 20000 | I16: 0.7 | J16: 4.727 | K16: 7.772 | L16: 0.95 | M16: 环合显示5
A17: 小吱 | B17: e2 | C17: E | E17: 106.4 | H17: =16000*IF(配装!$AR$5,1.25,1) -> 20000 | J17: 5.3 | K17: 8.9 | L17: 1.1 | M17: 环合显示9
A18: 小吱 | B18: e3 | C18: E | E18: 153.7 | H18: =16000*IF(配装!$AR$5,1.25,1) -> 20000 | J18: 7.701 | K18: 12.799 | L18: 1.5 | M18: 环合显示13
A19: 小吱 | B19: 长e半 | C19: E | E19: =59+25*16+153.7 -> 612.7 | H19: =(16000+4*16000)*IF(配装!$AR$5,1.25,1) -> 100000 | I19: 4 | J19: =J16+J18 -> 12.428 | K19: =K16+K18 -> 20.571 | L19: =L16+L18 -> 2.45
A20: 小吱 | B20: 长e满 | C20: E | E20: =59+25*32+153.7 -> 1012.7 | H20: =(16000+4*32000)*IF(配装!$AR$5,1.25,1) -> 180000 | J20: =J19 -> 12.428 | K20: =K19 -> 20.571 | L20: =L19 -> 2.45
A21: 小吱 | B21: q内e2 | C21: E | E21: 106.4 | H21: =24000*IF(配装!$AR$5,1.25,1) -> 30000 | J21: 5.3 | K21: 8.9 | L21: 1.1
A22: 小吱 | B22: q内满e1 | C22: E | E22: 59 | H22: =32000*IF(配装!$AR$5,1.25,1) -> 40000 | I22: 0.7 | J22: 4.727 | K22: 7.772 | L22: 0.95
A23: 小吱 | B23: q内满e2 | C23: E | E23: 106.4 | H23: =32000*IF(配装!$AR$5,1.25,1) -> 40000 | J23: 5.3 | K23: 8.9 | L23: 1.1
A24: 小吱 | B24: q内满e3 | C24: E | E24: 153.7 | H24: =32000*IF(配装!$AR$5,1.25,1) -> 40000 | J24: 7.701 | K24: 12.799 | L24: 1.5
A25: 小吱 | B25: q | C25: Q | E25: 500 | L25: 1.5
A26: 埃德嘉 | B26: 援护 | C26: 援护 | E26: 200 | I26: 1.3 | J26: 3.6 | L26: 2.5
A27: 埃德嘉 | B27: e | C27: E | E27: =80*7 -> 560 | J27: 22.4 | K27: 37.303 | L27: 4.501
A28: 埃德嘉 | B28: q | C28: Q | E28: 400 | L28: 1.5
A29: 娜娜莉 | B29: 援护 | C29: 援护 | E29: 200 | I29: 1.3 | J29: 7 | L29: 2.5
A30: 娜娜莉 | B30: C觉追击 | C30: 普攻 | D30: 追击 | E30: 50
A31: 娜娜莉 | B31: 天赋追击 | C31: 普攻 | D31: 追击 | E31: =60/配装!$AA$7 -> 30.014938
A32: 娜娜莉 | B32: 5a | C32: 普攻 | E32: 432.2 | I32: 3.85 | J32: 16.599 | K32: 27.7 | L32: 3.299 | M32: 环合显示33
A33: 娜娜莉 | B33: 5a副手 | C33: 普攻 | D33: 追击 | E33: =330 -> 330 | Q33: =IF(配装!$AU$7,30%,0) -> 0
A34: 娜娜莉 | B34: 3z | C34: 普攻 | E34: 339.7 | I34: 3.35 | J34: 13.101 | K34: 21.801 | L34: 2.6
A35: 娜娜莉 | B35: 3z副手 | C35: 普攻 | D35: 追击 | E35: 284.4 | Q35: =IF(配装!$AU$7,30%,0) -> 0
A36: 娜娜莉 | B36: 闪反 | C36: 闪反 | E36: 166 | I36: 2.1 | J36: 4.2 | K36: 6.9 | L36: 2.5
A37: 娜娜莉 | B37: 闪反副手 | C37: 普攻 | D37: 追击 | E37: 85.7 | Q37: =IF(配装!$AU$7,30%,0) -> 0
A38: 娜娜莉 | B38: 下落 | C38: 下落 | E38: 50 | I38: 0.5 | J38: 2.5 | K38: 4.2 | L38: 0.5
A39: 娜娜莉 | B39: 下落副手 | C39: 普攻 | D39: 追击 | E39: 50 | Q39: =IF(配装!$AU$7,30%,0) -> 0
A40: 娜娜莉 | B40: e | C40: E | E40: 500 | J40: 6.3 | K40: 10.4 | L40: 1.3 | M40: 环合显示12
...

Sheet 角色
A1: =COLUMN() -> 1 | B1: =COLUMN() -> 2 | C1: =COLUMN() -> 3 | D1: =COLUMN() -> 4 | E1: =COLUMN() -> 5 | F1: =COLUMN() -> 6 | G1: =COLUMN() -> 7 | H1: =COLUMN() -> 8 | ... AH1: =COLUMN() -> 34
A2: 角色 | B2: 属性 | C2: 星级 | D2: 攻击 | E2: 1级攻击 | F2: 生命 | G2: 1级生命 | H2: 防御 | I2: 1级防御 | J2: 暴击 | K2: 暴伤 | L2: 攻击% | M2: 攻击 | N2: 生命% | O2: 生命 | P2: 防御% | Q2: 防御 | R2: 减防 | S2: 减抗 | T2: 充能 | U2: 精通 | V2: 倾陷强度 | W2: 全伤 | X2: 属伤 | Y2: 普攻伤 | Z2: E伤 | AA2: Q伤 | AB2: 心灵伤 | AC2: 附着伤 | AD2: 追击伤 | AE2: 失衡增伤 | AF2: 大招消耗 | AG2: E冷却 | AH2: Q冷却
A3: 主角 | B3: 光 | C3: S | D3: =E3*7.95 -> 675.75 | E3: 85 | F3: =G3*12.12 -> 15150 | G3: 1250 | H3: =I3*12.12 -> 909 | I3: 75 | J3: 0.05 | K3: 0.5 | W3: 0.25 | AA3: =25%+IF(配装!AU3,25%,0) -> 0.5 | AF3: 100 | AG3: 16 | AH3: 15
A4: 浔 | B4: 光 | C4: S | D4: =E4*7.95 -> 636 | E4: 80 | F4: =G4*12.12 -> 15998.4 | G4: 1320 | H4: =I4*12.12 -> 909 | I4: 75 | J4: 0.05 | K4: 0.5 | AF4: 0 | AG4: 10 | AH4: 20
A5: 小吱 | B5: 光 | C5: S | D5: =E5*7.95 -> 659.85 | E5: 83 | F5: =G5*12.12 -> 15513.6 | G5: 1280 | H5: =I5*12.12 -> 909 | I5: 75 | J5: 0.05 | K5: 0.5 | S5: =IF(配装!AZ5,10%,0) -> 0 | X5: =IF(配装!AW5,20%,0) -> 0.2 | AF5: 100 | AG5: 3 | AH5: 15
A6: 埃德嘉 | B6: 光 | C6: A | D6: =E6*7.95 -> 421.35 | E6: 53 | F6: =G6*12.12 -> 16362 | G6: 1350 | H6: =I6*12.12 -> 824.16 | I6: 68 | J6: 0.05 | K6: 0.5 | AF6: 100 | AG6: 16 | AH6: 20
A7: 娜娜莉 | B7: 灵 | C7: S | D7: =E7*7.95 -> 636 | E7: 80 | F7: =G7*12.12 -> 15998.4 | G7: 1320 | H7: =I7*12.12 -> 909 | I7: 75 | J7: 0.05 | K7: 0.5 | L7: =IF(配装!AV7,20%,0) -> 0 | W7: =IF(配装!AZ7,10%,0) -> 0 | AF7: 100 | AG7: 16 | AH7: 15
A8: 九原 | B8: 灵 | C8: S | D8: =E8*7.95 -> 651.9 | E8: 82 | F8: =G8*12.12 -> 15634.8 | G8: 1290 | H8: =I8*12.12 -> 909 | I8: 75 | J8: 0.05 | K8: 0.5 | AF8: 100 | AG8: 16 | AH8: 15
A9: 薄荷 | B9: 灵 | C9: A | D9: =E9*7.95 -> 596.25 | E9: 75 | F9: =G9*12.12 -> 12120 | G9: 1000 | H9: =I9*12.12 -> 727.2 | I9: 60 | J9: =5%+IF(配装!$AU$9,IF(中间!$N$2,12%,0),0) -> 0.17 | K9: =50%+IF(配装!$AV$9,25%,0) -> 0.75 | P9: 0.2 | Z9: =IF(配装!$AS$9,40%,0) -> 0.4 | AF9: 100 | AG9: 6 | AH9: 15
A10: 白藏 | B10: 咒 | C10: S | D10: =E10*7.95 -> 643.95 | E10: 81 | F10: =G10*12.12 -> 16604.4 | G10: 1370 | H10: =I10*12.12 -> 799.92 | I10: 66 | J10: 0.05 | K10: 0.5 | AF10: 120 | AG10: 14/14 | AH10: 20
A11: 早雾 | B11: 咒 | C11: S | D11: =E11*7.95 -> 620.1 | E11: 78 | F11: =G11*12.12 -> 16483.2 | G11: 1360 | H11: =I11*12.12 -> 909 | I11: 75 | J11: 0.05 | K11: 0.5 | W11: =IF(配装!AZ11,云配队!H13*3%,0) -> 0 | AF11: 120 | AG11: 16 | AH11: 20
A12: 阿德勒 | B12: 咒 | C12: A | D12: =E12*7.95 -> 437.25 | E12: 55 | F12: =G12*12.12 -> 14301.6 | G12: 1180 | H12: =I12*12.12 -> 993.84 | I12: 82 | J12: 0.05 | K12: 0.5 | AF12: 120 | AG12: 16 | AH12: 20
A13: 安魂曲 | B13: 暗 | C13: S | D13: =E13*7.95 -> 636 | E13: 80 | F13: =G13*12.12 -> 15998.4 | G13: 1320 | H13: =I13*12.12 -> 909 | I13: 75 | J13: 0.05 | K13: 0.5 | M13: 200 | R13: =IF(配装!AZ13,10%,0) -> 0 | W13: =IF(配装!AS13,15%,0) -> 0 | AF13: 120 | AG13: 16 | AH13: 15
A14: 达芙蒂尔 | B14: 暗 | C14: S | D14: =E14*7.95 -> 643.95 | E14: 81 | F14: =G14*12.12 -> 16180.2 | G14: 1335 | H14: =I14*12.12 -> 872.64 | I14: 72 | J14: 0.05 | K14: 0.5 | AF14: 120 | AG14: 16 | AH14: 20
A15: 法帝娅 | B15: 魂 | C15: S | D15: =E15*7.95 -> 596.25 | E15: 75 | F15: =G15*12.12 -> 17089.2 | G15: 1410 | H15: =I15*12.12 -> 909 | I15: 75 | J15: 0.05 | K15: 0.5 | AF15: 120 | AG15: 16 | AH15: 20
A16: 哈尼娅 | B16: 魂 | C16: A | D16: =E16*7.95 -> 492.9 | E16: 62 | F16: =G16*12.12 -> 13695.6 | G16: 1130 | H16: =I16*12.12 -> 848.4 | I16: 70 | J16: 0.05 | K16: 0.5 | AF16: 120 | AG16: =IF(配装!AW16,16,20) -> 16 | AH16: 20
A17: 哈索尔 | B17: 相 | C17: S | D17: =E17*7.95 -> 643.95 | E17: 81 | F17: =G17*12.12 -> 15998.4 | G17: 1320 | H17: =I17*12.12 -> 884.76 | I17: 73 | J17: 0.05 | K17: 0.5 | AF17: 100 | AG17: 16 | AH17: 15
A18: 翳 | B18: 相 | C18: A | D18: =E18*7.95 -> 556.5 | E18: 70 | F18: =G18*12.12 -> 13332 | G18: 1100 | H18: =I18*12.12 -> 666.6 | I18: 55 | J18: =5%+IF(配装!AS18,10%,0) -> 0.15 | K18: 0.5 | W18: =IF(配装!AT18,8%,0) -> 0.08 | AF18: 100 | AG18: 15 | AH18: 15

Sheet 天赋
A1: =COLUMN() -> 1 | B1: =COLUMN() -> 2 | C1: =COLUMN() -> 3 | D1: =COLUMN() -> 4 | E1: =COLUMN() -> 5 | F1: =COLUMN() -> 6 | G1: =COLUMN() -> 7 | H1: =COLUMN() -> 8 | I1: =COLUMN() -> 9
A2: 角色 | B2: 激活 | C2: 创生株数 | D2: 创生朵数 | E2: 浊燃增伤
A3: 主角 | B3: =ISNUMBER(MATCH(A3,云配队!$F$4:$F$7,0)) -> TRUE
A4: 浔 | B4: =ISNUMBER(MATCH(A4,云配队!$F$4:$F$7,0)) -> FALSE
A5: 小吱 | B5: =ISNUMBER(MATCH(A5,云配队!$F$4:$F$7,0)) -> FALSE
A6: 埃德嘉 | B6: =ISNUMBER(MATCH(A6,云配队!$F$4:$F$7,0)) -> FALSE
A7: 娜娜莉 | B7: =ISNUMBER(MATCH(A7,云配队!$F$4:$F$7,0)) -> TRUE | D7: 1
A8: 九原 | B8: =ISNUMBER(MATCH(A8,云配队!$F$4:$F$7,0)) -> TRUE | C8: 1
A9: 薄荷 | B9: =ISNUMBER(MATCH(A9,云配队!$F$4:$F$7,0)) -> FALSE
A10: 白藏 | B10: =ISNUMBER(MATCH(A10,云配队!$F$4:$F$7,0)) -> FALSE
A11: 早雾 | B11: =ISNUMBER(MATCH(A11,云配队!$F$4:$F$7,0)) -> FALSE | E11: =25%*云配队!H13 -> 0
A12: 阿德勒 | B12: =ISNUMBER(MATCH(A12,云配队!$F$4:$F$7,0)) -> TRUE
A13: 安魂曲 | B13: =ISNUMBER(MATCH(A13,云配队!$F$4:$F$7,0)) -> FALSE
A14: 达芙蒂尔 | B14: =ISNUMBER(MATCH(A14,云配队!$F$4:$F$7,0)) -> FALSE
A15: 法帝娅 | B15: =ISNUMBER(MATCH(A15,云配队!$F$4:$F$7,0)) -> FALSE
A16: 哈尼娅 | B16: =ISNUMBER(MATCH(A16,云配队!$F$4:$F$7,0)) -> FALSE
A17: 哈索尔 | B17: =ISNUMBER(MATCH(A17,云配队!$F$4:$F$7,0)) -> FALSE
A18: 翳 | B18: =ISNUMBER(MATCH(A18,云配队!$F$4:$F$7,0)) -> FALSE

Sheet 弧盘
A1: =COLUMN() -> 1 | B1: =COLUMN() -> 2 | C1: =COLUMN() -> 3 | D1: =COLUMN() -> 4 | E1: =COLUMN() -> 5 | F1: =COLUMN() -> 6 | G1: =COLUMN() -> 7 | H1: =COLUMN() -> 8 | ... AH1: =COLUMN() -> 34
A2: 弧盘 | B2: 80级攻击 | C2: 1级攻击 | D2: 星级 | E2: 获取 | F2: 适配 | G2: 暴击 | H2: 暴伤 | I2: 攻击 | J2: 生命 | K2: 防御 | L2: 充能 | M2: 精通 | N2: 倾陷强度 | O2: 详情 | P2: 暴击 | Q2: 暴伤 | R2: 攻击 | S2: 生命 | T2: 防御 | U2: 充能 | V2: 精通 | W2: 倾陷强度 | X2: 全伤 | Y2: 属伤 | Z2: 普攻增伤 | AA2: E增伤 | AB2: Q增伤 | AC2: 潜意增伤 | AD2: 附着增伤 | AE2: 追击增伤 | AF2: 失衡增伤 | AG2: 治疗效率 | AH2: 护盾强度
A3: 行进于时间之外 | B3: 570 | C3: 37 | D3: S | E3: 限定研募 | F3: 固态 | G3: 0.24 | O3: 16攻击；e后每秒q的45暴伤和12减防 | R3: 0.16
A4: 无畏之棉 | B4: 512 | C4: 33 | D4: S | E4: 大月卡 | F4: 固态 | G4: 0.22 | O4: Q后25攻击 | R4: 0.25
A5: 无畏之棉·满精 | B5: 512 | C5: 33 | D5: S | E5: 大月卡 | F5: 固态 | G5: 0.22 | O5: Q后45攻击 | R5: 0.45
A6: 千金难买你开心 | B6: 512 | C6: 33 | D6: S | E6: 许愿币 | F6: 固态 | K6: 0.385 | O6: 24生命；q后回复效果 | S6: 0.24
A7: 海特洛的安宁 | B7: 570 | C7: 37 | D7: S | E7: 通行正义 | F7: 固态 | I7: 0.275 | O7: 15攻击；对boss15增伤；调弧：协同30秒，CD60秒 | R7: 0.15 | X7: 0.15
A8: 休息日 | B8: 512 | C8: 33 | D8: S | E8: 日蚀 | F8: 固态 | L8: 0.33 | O8: 30攻击；调弧：对群回能 | R8: 0.3
A9: 现实避难所 | B9: 570 | C9: 37 | D9: S | E9: 斑蝶 | F9: 固态 | I9: 0.3 | O9: 15灵伤；10附着伤，q后改20附着伤 | Y9: 0.15 | AD9: 0.3
A10: 引爆全场 | B10: 512 | C10: 33 | D10: S | E10: 音霸魔王 | F10: 固态 | I10: 0.275 | O10: 12-32%魂伤 | Y10: 0.12
A11: 引爆全场外借 | B11: 512 | C11: 33 | D11: S | E11: 音霸魔王 | F11: 固态 | I11: 0.275
A12: 时间大盗 | B12: 475 | C12: 31 | D12: A | E12: 撬撬（未发现） | F12: 固态 | J12: 0.25 | O12: e后162倾陷，10s；调弧开锁 | W12: 162
A13: 被遗忘者 | B13: 475 | C13: 31 | D13: A | E13: 无画框&集市 | F13: 固态 | J13: 0.25 | O13: 36攻击；残血改36防御 | R13: 0.36
A14: 成功的第一步 | B14: 380 | C14: 24 | D14: B | E14: 集市 | F14: 固态 | I14: 0.2 | O14: e后16攻击，10s，cd20s | R14: 0.16
A15: 「最后一朵玫瑰」 | B15: 570 | C15: 37 | D15: S | E15: 限定研募 | F15: 液态 | G15: 0.24 | O15: 14攻击；叠层60暴伤；倾陷延时3s | Q15: 0.6 | R15: 0.14
A16: 极速之棉 | B16: 512 | C16: 33 | D16: S | E16: 大月卡 | F16: 液态 | H16: 0.44 | O16: 前台驻场每秒5攻击5层 | R16: =5%*5 -> 0.25
A17: 极速之棉·满精 | B17: 512 | C17: 33 | D17: S | E17: 大月卡 | F17: 液态 | H17: 0.44 | O17: 前台驻场每秒9攻击5层 | R17: 0.45
A18: 漆黑青春妄想 | B18: 570 | C18: 37 | D18: S | E18: 黑之书 | F18: 液态 | I18: 0.3 | O18: 60倾陷；调弧：20暗伤、倾陷200%倍率 | W18: 60
A19: 扭曲之城的呼唤 | B19: 395 | C19: 25 | D19: A | E19: 瓦楞城堡 | F19: 液态 | J19: 0.375 | O19: e后治疗效率20%
A20: 闪耀每一天 | B20: 475 | C20: 31 | D20: A | E20: 胶卷-MANISHI | F20: 液态 | I20: 0.25 | O20: 84倾陷强度；失衡增伤18% | W20: 84 | AF20: 0.18
A21: 灵感大逃杀 | B21: 555 | C21: 36 | D21: A | E21: 灵感终结者 | F21: 液态 | N21: 60 | O21: E后18能量，20秒cd
A22: 开始净空 | B22: 475 | C22: 31 | D22: A | E22: 纸翼战队&集市 | F22: 液态 | I22: 0.25 | O22: EQ35灵伤 | AA22: 0.35 | AB22: 0.35
A23: 电音狂欢 | B23: 380 | C23: 24 | D23: B | E23: 集市 | F23: 液态 | I23: 0.25 | O23: e伤16% | AA23: 0.16
A24: 灵敏之棉 | B24: 512 | C24: 33 | D24: S | E24: 大月卡 | F24: 气态 | I24: 0.275 | O24: 闪反8%增伤；3层10秒
A25: 灵敏之棉·满精 | B25: 512 | C25: 33 | D25: S | E25: 大月卡 | F25: 气态 | I25: 0.275 | O25: 闪反14.4%增伤；3层10秒
A26: 思考喵 | B26: 512 | C26: 33 | D26: S | E26: 都市大亨 | F26: 气态 | H26: 0.44 | O26: 100万方斯叠满25光伤 | Y26: 0.25
A27: 思考喵·满精 | B27: 512 | C27: 33 | D27: S | E27: 都市大亨 | F27: 气态 | H27: 0.44 | O27: 100万方斯叠满45光伤 | Y27: 0.45
A28: 面具下的泪 | B28: 512 | C28: 33 | D28: S | E28: 囿巢鸟 | F28: 气态 | I28: 0.275 | O28: Q命中敌人减攻
A29: 好狗狗走四方 | B29: 474 | C29: 31 | D29: S | E29: 墨菲克斯 | F29: 气态 | I29: 0.45 | O29: 18充能；Q后全队10%攻击，控住额外6%，20秒 | U29: 0.18
A30: 光波眩晕，迷走狂欢 | B30: 475 | C30: 31 | D30: A | E30: 波普 | F30: 气态 | I30: 0.25 | O30: 援护技后10秒内造成的伤害提高30%。20秒一次。 | X30: 0.3
A31: 当心头顶 | B31: 475 | C31: 31 | D31: A | E31: 诡面筝&集市 | F31: 气态 | H31: 0.4 | O31: E后18%攻击力，相环合敌人下，额外18%相伤，持续15秒 | R31: 0.18 | Y31: 0.18
A32: 挂你在心口难开 | B32: 475 | C32: 31 | D32: A | E32: 蜘识藏家 | F32: 气态 | N32: 48 | O32: 普攻叠8层后，Q后全队16攻击
A33: 笑口常开 | B33: 316 | C33: 31 | D33: B | E33: 集市 | F33: 气态 | J33: 0.3 | O33: 杀敌回血
A34: 预备备 | B34: 570 | C34: 37 | D34: S | E34: 限定研募 | F34: 等离子 | G34: 0.24 | O34: 15攻击；eq后普攻增伤15%，15秒2层；调弧(eq)：10对boss增伤，10秒 | R34: 0.15 | Z34: 0.15 | AB34: 0.1
A35: 不屈之绵 | B35: 512 | C35: 33 | D35: S | E35: 大月卡 | F35: 等离子 | I35: 0.275 | O35: 22增伤；半血下提升至28% | X35: 0.25
A36: 不屈之绵·满精 | B36: 512 | C36: 33 | D36: S | E36: 大月卡 | F36: 等离子 | I36: 0.275 | O36: 38增伤；半血下提升至52% | X36: 0.45
A37: 鲸之歌 | B37: 512 | C37: 33 | D37: S | E37: 深蓝之恸 | F37: 等离子 | I37: 0.275 | O37: 12%攻击，倾陷增伤12%
A38: 焰魂狂飙 | B38: 666 | C38: 43 | D38: S | E38: 无首铁驭 | F38: 等离子 | H38: 0.24 | O38: Q后22.5E伤，每次额外提升15
A39: 拔刀 | B39: 395 | C39: 25 | D39: A | E39: 血染妖刀&集市 | F39: 等离子 | I39: 0.375 | O39: 招架额外200%倍率咒伤
A40: 欧拉欧拉！ | B40: 395 | C40: 25 | D40: A | E40: 欧拉拳套 | F40: 等离子 | I40: 0.375 | O40: 叠层普伤3.6*10,10秒 | Z40: =36%*0.5 -> 0.18
...

Sheet 卡带
A1: =COLUMN() -> 1 | B1: =COLUMN() -> 2 | C1: =COLUMN() -> 3 | D1: =COLUMN() -> 4 | E1: =COLUMN() -> 5 | F1: =COLUMN() -> 6 | G1: =COLUMN() -> 7 | H1: =COLUMN() -> 8 | ... V1: =COLUMN() -> 22
A2: 卡带 | B2: 增伤 | C2: 攻击 | D2: 生命 | E2: 防御 | F2: 充能 | G2: 精通 | H2: 倾陷强度 | I2: 心灵增伤 | J2: 详情 | K2: 减防 | L2: 减抗 | M2: 暴击 | N2: 暴伤 | O2: 攻击 | P2: 生命 | Q2: 全伤 | R2: 属伤 | S2: 普攻增伤 | T2: E增伤 | U2: Q增伤 | V2: 心灵增伤
